[05/May/2015 17:18:48] ERROR [django.request:231] Internal Server Error: /sig/expedientes/buscar/Expediente/
Traceback (most recent call last):
  File "/opt/virtualenvs3/lib/python3.4/site-packages/django/db/backends/utils.py", line 65, in execute
    return self.cursor.execute(sql, params)
psycopg2.ProgrammingError: column documentos_expediente.fechaInicio does not exist
LINE 1: ...caracteristica", "documentos_expediente"."fecha", "documento...
                                                             ^


The above exception was the direct cause of the following exception:

Traceback (most recent call last):
  File "/opt/virtualenvs3/lib/python3.4/site-packages/django/core/handlers/base.py", line 111, in get_response
    response = wrapped_callback(request, *callback_args, **callback_kwargs)
  File "/opt/virtualenvs3/lib/python3.4/site-packages/django/contrib/auth/decorators.py", line 21, in _wrapped_view
    return view_func(request, *args, **kwargs)
  File "/home/mmanto/sstuv/documentos/views.py", line 135, in showResultados
    return render_to_response('expedienteley_list.html', {'expedientes' : expedientes, 'tipo' : tipo, 'organismoFiltro' : organismo, 'numeroFiltro': numero, 'fecha_inicioFiltro' :fecha_inicio, 'alcanceFiltro': alcance, 'expPropiosFiltro':buscarExpPropios}, context_instance=RequestContext(request))
  File "/opt/virtualenvs3/lib/python3.4/site-packages/django/shortcuts.py", line 25, in render_to_response
    return HttpResponse(loader.render_to_string(*args, **kwargs), **httpresponse_kwargs)
  File "/opt/virtualenvs3/lib/python3.4/site-packages/django/template/loader.py", line 178, in render_to_string
    return t.render(context_instance)
  File "/opt/virtualenvs3/lib/python3.4/site-packages/django/template/base.py", line 148, in render
    return self._render(context)
  File "/opt/virtualenvs3/lib/python3.4/site-packages/django/template/base.py", line 142, in _render
    return self.nodelist.render(context)
  File "/opt/virtualenvs3/lib/python3.4/site-packages/django/template/base.py", line 844, in render
    bit = self.render_node(node, context)
  File "/opt/virtualenvs3/lib/python3.4/site-packages/django/template/debug.py", line 80, in render_node
    return node.render(context)
  File "/opt/virtualenvs3/lib/python3.4/site-packages/django/template/loader_tags.py", line 126, in render
    return compiled_parent._render(context)
  File "/opt/virtualenvs3/lib/python3.4/site-packages/django/template/base.py", line 142, in _render
    return self.nodelist.render(context)
  File "/opt/virtualenvs3/lib/python3.4/site-packages/django/template/base.py", line 844, in render
    bit = self.render_node(node, context)
  File "/opt/virtualenvs3/lib/python3.4/site-packages/django/template/debug.py", line 80, in render_node
    return node.render(context)
  File "/opt/virtualenvs3/lib/python3.4/site-packages/django/template/loader_tags.py", line 126, in render
    return compiled_parent._render(context)
  File "/opt/virtualenvs3/lib/python3.4/site-packages/django/template/base.py", line 142, in _render
    return self.nodelist.render(context)
  File "/opt/virtualenvs3/lib/python3.4/site-packages/django/template/base.py", line 844, in render
    bit = self.render_node(node, context)
  File "/opt/virtualenvs3/lib/python3.4/site-packages/django/template/debug.py", line 80, in render_node
    return node.render(context)
  File "/opt/virtualenvs3/lib/python3.4/site-packages/django/template/loader_tags.py", line 65, in render
    result = block.nodelist.render(context)
  File "/opt/virtualenvs3/lib/python3.4/site-packages/django/template/base.py", line 844, in render
    bit = self.render_node(node, context)
  File "/opt/virtualenvs3/lib/python3.4/site-packages/django/template/debug.py", line 80, in render_node
    return node.render(context)
  File "/opt/virtualenvs3/lib/python3.4/site-packages/django/template/defaulttags.py", line 162, in render
    len_values = len(values)
  File "/opt/virtualenvs3/lib/python3.4/site-packages/django/core/paginator.py", line 117, in __len__
    return len(self.object_list)
  File "/opt/virtualenvs3/lib/python3.4/site-packages/django/db/models/query.py", line 122, in __len__
    self._fetch_all()
  File "/opt/virtualenvs3/lib/python3.4/site-packages/django/db/models/query.py", line 966, in _fetch_all
    self._result_cache = list(self.iterator())
  File "/opt/virtualenvs3/lib/python3.4/site-packages/django/db/models/query.py", line 265, in iterator
    for row in compiler.results_iter():
  File "/opt/virtualenvs3/lib/python3.4/site-packages/django/db/models/sql/compiler.py", line 700, in results_iter
    for rows in self.execute_sql(MULTI):
  File "/opt/virtualenvs3/lib/python3.4/site-packages/django/db/models/sql/compiler.py", line 786, in execute_sql
    cursor.execute(sql, params)
  File "/opt/virtualenvs3/lib/python3.4/site-packages/django/db/backends/utils.py", line 81, in execute
    return super(CursorDebugWrapper, self).execute(sql, params)
  File "/opt/virtualenvs3/lib/python3.4/site-packages/django/db/backends/utils.py", line 65, in execute
    return self.cursor.execute(sql, params)
  File "/opt/virtualenvs3/lib/python3.4/site-packages/django/db/utils.py", line 94, in __exit__
    six.reraise(dj_exc_type, dj_exc_value, traceback)
  File "/opt/virtualenvs3/lib/python3.4/site-packages/django/utils/six.py", line 658, in reraise
    raise value.with_traceback(tb)
  File "/opt/virtualenvs3/lib/python3.4/site-packages/django/db/backends/utils.py", line 65, in execute
    return self.cursor.execute(sql, params)
django.db.utils.ProgrammingError: column documentos_expediente.fechaInicio does not exist
LINE 1: ...caracteristica", "documentos_expediente"."fecha", "documento...
                                                             ^

[05/May/2015 17:18:49] ERROR [django.request:231] Internal Server Error: /sig/expedientes/buscar/Expediente/
Traceback (most recent call last):
  File "/opt/virtualenvs3/lib/python3.4/site-packages/django/db/backends/utils.py", line 65, in execute
    return self.cursor.execute(sql, params)
psycopg2.ProgrammingError: column documentos_expediente.fechaInicio does not exist
LINE 1: ...caracteristica", "documentos_expediente"."fecha", "documento...
                                                             ^


The above exception was the direct cause of the following exception:

Traceback (most recent call last):
  File "/opt/virtualenvs3/lib/python3.4/site-packages/django/core/handlers/base.py", line 111, in get_response
    response = wrapped_callback(request, *callback_args, **callback_kwargs)
  File "/opt/virtualenvs3/lib/python3.4/site-packages/django/contrib/auth/decorators.py", line 21, in _wrapped_view
    return view_func(request, *args, **kwargs)
  File "/home/mmanto/sstuv/documentos/views.py", line 135, in showResultados
    return render_to_response('expedienteley_list.html', {'expedientes' : expedientes, 'tipo' : tipo, 'organismoFiltro' : organismo, 'numeroFiltro': numero, 'fecha_inicioFiltro' :fecha_inicio, 'alcanceFiltro': alcance, 'expPropiosFiltro':buscarExpPropios}, context_instance=RequestContext(request))
  File "/opt/virtualenvs3/lib/python3.4/site-packages/django/shortcuts.py", line 25, in render_to_response
    return HttpResponse(loader.render_to_string(*args, **kwargs), **httpresponse_kwargs)
  File "/opt/virtualenvs3/lib/python3.4/site-packages/django/template/loader.py", line 178, in render_to_string
    return t.render(context_instance)
  File "/opt/virtualenvs3/lib/python3.4/site-packages/django/template/base.py", line 148, in render
    return self._render(context)
  File "/opt/virtualenvs3/lib/python3.4/site-packages/django/template/base.py", line 142, in _render
    return self.nodelist.render(context)
  File "/opt/virtualenvs3/lib/python3.4/site-packages/django/template/base.py", line 844, in render
    bit = self.render_node(node, context)
  File "/opt/virtualenvs3/lib/python3.4/site-packages/django/template/debug.py", line 80, in render_node
    return node.render(context)
  File "/opt/virtualenvs3/lib/python3.4/site-packages/django/template/loader_tags.py", line 126, in render
    return compiled_parent._render(context)
  File "/opt/virtualenvs3/lib/python3.4/site-packages/django/template/base.py", line 142, in _render
    return self.nodelist.render(context)
  File "/opt/virtualenvs3/lib/python3.4/site-packages/django/template/base.py", line 844, in render
    bit = self.render_node(node, context)
  File "/opt/virtualenvs3/lib/python3.4/site-packages/django/template/debug.py", line 80, in render_node
    return node.render(context)
  File "/opt/virtualenvs3/lib/python3.4/site-packages/django/template/loader_tags.py", line 126, in render
    return compiled_parent._render(context)
  File "/opt/virtualenvs3/lib/python3.4/site-packages/django/template/base.py", line 142, in _render
    return self.nodelist.render(context)
  File "/opt/virtualenvs3/lib/python3.4/site-packages/django/template/base.py", line 844, in render
    bit = self.render_node(node, context)
  File "/opt/virtualenvs3/lib/python3.4/site-packages/django/template/debug.py", line 80, in render_node
    return node.render(context)
  File "/opt/virtualenvs3/lib/python3.4/site-packages/django/template/loader_tags.py", line 65, in render
    result = block.nodelist.render(context)
  File "/opt/virtualenvs3/lib/python3.4/site-packages/django/template/base.py", line 844, in render
    bit = self.render_node(node, context)
  File "/opt/virtualenvs3/lib/python3.4/site-packages/django/template/debug.py", line 80, in render_node
    return node.render(context)
  File "/opt/virtualenvs3/lib/python3.4/site-packages/django/template/defaulttags.py", line 162, in render
    len_values = len(values)
  File "/opt/virtualenvs3/lib/python3.4/site-packages/django/core/paginator.py", line 117, in __len__
    return len(self.object_list)
  File "/opt/virtualenvs3/lib/python3.4/site-packages/django/db/models/query.py", line 122, in __len__
    self._fetch_all()
  File "/opt/virtualenvs3/lib/python3.4/site-packages/django/db/models/query.py", line 966, in _fetch_all
    self._result_cache = list(self.iterator())
  File "/opt/virtualenvs3/lib/python3.4/site-packages/django/db/models/query.py", line 265, in iterator
    for row in compiler.results_iter():
  File "/opt/virtualenvs3/lib/python3.4/site-packages/django/db/models/sql/compiler.py", line 700, in results_iter
    for rows in self.execute_sql(MULTI):
  File "/opt/virtualenvs3/lib/python3.4/site-packages/django/db/models/sql/compiler.py", line 786, in execute_sql
    cursor.execute(sql, params)
  File "/opt/virtualenvs3/lib/python3.4/site-packages/django/db/backends/utils.py", line 81, in execute
    return super(CursorDebugWrapper, self).execute(sql, params)
  File "/opt/virtualenvs3/lib/python3.4/site-packages/django/db/backends/utils.py", line 65, in execute
    return self.cursor.execute(sql, params)
  File "/opt/virtualenvs3/lib/python3.4/site-packages/django/db/utils.py", line 94, in __exit__
    six.reraise(dj_exc_type, dj_exc_value, traceback)
  File "/opt/virtualenvs3/lib/python3.4/site-packages/django/utils/six.py", line 658, in reraise
    raise value.with_traceback(tb)
  File "/opt/virtualenvs3/lib/python3.4/site-packages/django/db/backends/utils.py", line 65, in execute
    return self.cursor.execute(sql, params)
django.db.utils.ProgrammingError: column documentos_expediente.fechaInicio does not exist
LINE 1: ...caracteristica", "documentos_expediente"."fecha", "documento...
                                                             ^

[05/May/2015 17:33:33] INFO [sstuvInfo:84] busqueda de expedientes en logger info
[05/May/2015 17:34:16] INFO [sstuvInfo:84] busqueda de expedientes en logger info
[05/May/2015 17:34:34] WARNING [django.request:143] Not Found: /sig/auth/logout/
[05/May/2015 17:35:01] INFO [sstuvInfo:84] busqueda de expedientes en logger info
[05/May/2015 17:36:08] INFO [sstuvInfo:84] busqueda de expedientes en logger info
[05/May/2015 17:38:38] INFO [sstuvInfo:84] busqueda de expedientes en logger info
[05/May/2015 17:40:12] WARNING [django.request:143] Not Found: /sig/auth/logout/
[05/May/2015 17:40:17] WARNING [django.request:143] Not Found: /sig/auth/logout/
[05/May/2015 17:40:34] INFO [sstuvInfo:84] busqueda de expedientes en logger info
[05/May/2015 17:57:45] WARNING [django.request:143] Not Found: /sig/publicador/principal
[05/May/2015 17:58:22] WARNING [django.request:143] Not Found: /sig/publicador/principal
[05/May/2015 17:58:26] INFO [sstuvInfo:84] busqueda de expedientes en logger info
[05/May/2015 18:01:53] INFO [sstuvInfo:84] busqueda de expedientes en logger info
[05/May/2015 18:01:54] WARNING [django.request:143] Not Found: /sig/publicador/principal
[05/May/2015 18:02:24] WARNING [django.request:143] Not Found: /sig/publicador/principal/
[05/May/2015 18:02:42] WARNING [django.request:143] Not Found: /sig/publicador/principal/
[05/May/2015 18:02:52] INFO [sstuvInfo:84] busqueda de expedientes en logger info
[05/May/2015 18:12:09] WARNING [django.request:143] Not Found: /sig/publicador/principal
[05/May/2015 18:16:50] WARNING [django.request:143] Not Found: /sig/publicador/principal
[05/May/2015 18:16:51] WARNING [django.request:143] Not Found: /sig/publicador/principal
[05/May/2015 18:16:51] WARNING [django.request:143] Not Found: /sig/publicador/principal
[05/May/2015 18:16:52] WARNING [django.request:143] Not Found: /sig/publicador/principal
[05/May/2015 18:16:52] WARNING [django.request:143] Not Found: /sig/publicador/principal
[05/May/2015 18:16:52] WARNING [django.request:143] Not Found: /sig/publicador/principal
[05/May/2015 18:16:52] WARNING [django.request:143] Not Found: /sig/publicador/principal
[05/May/2015 18:16:52] WARNING [django.request:143] Not Found: /sig/publicador/principal
[05/May/2015 18:21:14] WARNING [django.request:143] Not Found: /sig/publicador/principal/
[05/May/2015 18:28:53] ERROR [django.request:231] Internal Server Error: /sig/publicador/principal/
Traceback (most recent call last):
  File "/opt/virtualenvs3/lib/python3.4/site-packages/django/db/backends/utils.py", line 65, in execute
    return self.cursor.execute(sql, params)
psycopg2.ProgrammingError: column publicador_articulo.imagen does not exist
LINE 1: ...ntenido", "publicador_articulo"."fecha_creacion", "publicado...
                                                             ^


The above exception was the direct cause of the following exception:

Traceback (most recent call last):
  File "/opt/virtualenvs3/lib/python3.4/site-packages/django/core/handlers/base.py", line 111, in get_response
    response = wrapped_callback(request, *callback_args, **callback_kwargs)
  File "/home/mmanto/sstuv/publicador/views.py", line 115, in principal
    articulo = Articulo.objects.first()
  File "/opt/virtualenvs3/lib/python3.4/site-packages/django/db/models/manager.py", line 92, in manager_method
    return getattr(self.get_queryset(), name)(*args, **kwargs)
  File "/opt/virtualenvs3/lib/python3.4/site-packages/django/db/models/query.py", line 510, in first
    return qs[0]
  File "/opt/virtualenvs3/lib/python3.4/site-packages/django/db/models/query.py", line 177, in __getitem__
    return list(qs)[0]
  File "/opt/virtualenvs3/lib/python3.4/site-packages/django/db/models/query.py", line 141, in __iter__
    self._fetch_all()
  File "/opt/virtualenvs3/lib/python3.4/site-packages/django/db/models/query.py", line 966, in _fetch_all
    self._result_cache = list(self.iterator())
  File "/opt/virtualenvs3/lib/python3.4/site-packages/django/db/models/query.py", line 265, in iterator
    for row in compiler.results_iter():
  File "/opt/virtualenvs3/lib/python3.4/site-packages/django/db/models/sql/compiler.py", line 700, in results_iter
    for rows in self.execute_sql(MULTI):
  File "/opt/virtualenvs3/lib/python3.4/site-packages/django/db/models/sql/compiler.py", line 786, in execute_sql
    cursor.execute(sql, params)
  File "/opt/virtualenvs3/lib/python3.4/site-packages/django/db/backends/utils.py", line 81, in execute
    return super(CursorDebugWrapper, self).execute(sql, params)
  File "/opt/virtualenvs3/lib/python3.4/site-packages/django/db/backends/utils.py", line 65, in execute
    return self.cursor.execute(sql, params)
  File "/opt/virtualenvs3/lib/python3.4/site-packages/django/db/utils.py", line 94, in __exit__
    six.reraise(dj_exc_type, dj_exc_value, traceback)
  File "/opt/virtualenvs3/lib/python3.4/site-packages/django/utils/six.py", line 658, in reraise
    raise value.with_traceback(tb)
  File "/opt/virtualenvs3/lib/python3.4/site-packages/django/db/backends/utils.py", line 65, in execute
    return self.cursor.execute(sql, params)
django.db.utils.ProgrammingError: column publicador_articulo.imagen does not exist
LINE 1: ...ntenido", "publicador_articulo"."fecha_creacion", "publicado...
                                                             ^

[05/May/2015 18:58:38] INFO [sstuvInfo:84] busqueda de expedientes en logger info
[05/May/2015 19:11:05] WARNING [django.request:143] Not Found: /sig/auth/logout
[05/May/2015 19:22:27] WARNING [django.request:143] Not Found: /sig/publicador/aArticuloDesdeImagen/29
[05/May/2015 19:23:28] INFO [sstuvInfo:84] busqueda de expedientes en logger info
[05/May/2015 19:23:36] WARNING [django.request:143] Not Found: /sig/publicador/aArticuloDesdeImagen/29
[05/May/2015 19:28:18] WARNING [django.request:143] Not Found: /sig/publicador/aArticuloDesdeImagen/29
[05/May/2015 19:28:24] WARNING [django.request:143] Not Found: /sig/publicador/
[06/May/2015 14:13:49] INFO [sstuvInfo:84] busqueda de expedientes en logger info
[06/May/2015 14:13:50] WARNING [django.request:143] Not Found: /favicon.ico
[06/May/2015 14:20:57] ERROR [django.request:231] Internal Server Error: /sig/expedientesLey/
Traceback (most recent call last):
  File "/home/mmanto/virtualenvs3/python3.4/lib/python3.4/site-packages/django/template/base.py", line 286, in parse
    compile_func = self.tags[command]
KeyError: 'endblock'

During handling of the above exception, another exception occurred:

Traceback (most recent call last):
  File "/home/mmanto/virtualenvs3/python3.4/lib/python3.4/site-packages/django/core/handlers/base.py", line 111, in get_response
    response = wrapped_callback(request, *callback_args, **callback_kwargs)
  File "/home/mmanto/virtualenvs3/python3.4/lib/python3.4/site-packages/django/contrib/auth/decorators.py", line 21, in _wrapped_view
    return view_func(request, *args, **kwargs)
  File "/home/mmanto/git/sstuv/documentos/views.py", line 90, in loadBusquedaExpedienteLey
    return render(request, 'expedienteley_list.html', {'tipo' : 'ExpedienteLey'}, context_instance=RequestContext(request))
  File "/home/mmanto/virtualenvs3/python3.4/lib/python3.4/site-packages/django/shortcuts.py", line 50, in render
    return HttpResponse(loader.render_to_string(*args, **kwargs),
  File "/home/mmanto/virtualenvs3/python3.4/lib/python3.4/site-packages/django/template/loader.py", line 170, in render_to_string
    t = get_template(template_name, dirs)
  File "/home/mmanto/virtualenvs3/python3.4/lib/python3.4/site-packages/django/template/loader.py", line 144, in get_template
    template, origin = find_template(template_name, dirs)
  File "/home/mmanto/virtualenvs3/python3.4/lib/python3.4/site-packages/django/template/loader.py", line 132, in find_template
    source, display_name = loader(name, dirs)
  File "/home/mmanto/virtualenvs3/python3.4/lib/python3.4/site-packages/django/template/loader.py", line 44, in __call__
    return self.load_template(template_name, template_dirs)
  File "/home/mmanto/virtualenvs3/python3.4/lib/python3.4/site-packages/django/template/loader.py", line 50, in load_template
    template = get_template_from_string(source, origin, template_name)
  File "/home/mmanto/virtualenvs3/python3.4/lib/python3.4/site-packages/django/template/loader.py", line 156, in get_template_from_string
    return Template(source, origin, name)
  File "/home/mmanto/virtualenvs3/python3.4/lib/python3.4/site-packages/django/template/base.py", line 132, in __init__
    self.nodelist = compile_string(template_string, origin)
  File "/home/mmanto/virtualenvs3/python3.4/lib/python3.4/site-packages/django/template/base.py", line 162, in compile_string
    return parser.parse()
  File "/home/mmanto/virtualenvs3/python3.4/lib/python3.4/site-packages/django/template/base.py", line 290, in parse
    compiled_result = compile_func(self, token)
  File "/home/mmanto/virtualenvs3/python3.4/lib/python3.4/site-packages/django/template/loader_tags.py", line 201, in do_extends
    nodelist = parser.parse()
  File "/home/mmanto/virtualenvs3/python3.4/lib/python3.4/site-packages/django/template/base.py", line 290, in parse
    compiled_result = compile_func(self, token)
  File "/home/mmanto/virtualenvs3/python3.4/lib/python3.4/site-packages/django/template/loader_tags.py", line 175, in do_block
    nodelist = parser.parse(('endblock',))
  File "/home/mmanto/virtualenvs3/python3.4/lib/python3.4/site-packages/django/template/base.py", line 290, in parse
    compiled_result = compile_func(self, token)
  File "/home/mmanto/virtualenvs3/python3.4/lib/python3.4/site-packages/django/template/defaulttags.py", line 989, in do_if
    nodelist = parser.parse(('endif',))
  File "/home/mmanto/virtualenvs3/python3.4/lib/python3.4/site-packages/django/template/base.py", line 288, in parse
    self.invalid_block_tag(token, command, parse_until)
  File "/home/mmanto/virtualenvs3/python3.4/lib/python3.4/site-packages/django/template/base.py", line 343, in invalid_block_tag
    (command, get_text_list(["'%s'" % p for p in parse_until])))
django.template.base.TemplateSyntaxError: Invalid block tag: 'endblock', expected 'endif'
[06/May/2015 14:23:25] ERROR [django.request:231] Internal Server Error: /sig/expedientesLey/
Traceback (most recent call last):
  File "/home/mmanto/virtualenvs3/python3.4/lib/python3.4/site-packages/django/core/handlers/base.py", line 111, in get_response
    response = wrapped_callback(request, *callback_args, **callback_kwargs)
  File "/home/mmanto/virtualenvs3/python3.4/lib/python3.4/site-packages/django/contrib/auth/decorators.py", line 21, in _wrapped_view
    return view_func(request, *args, **kwargs)
  File "/home/mmanto/git/sstuv/documentos/views.py", line 90, in loadBusquedaExpedienteLey
    return render(request, 'expedienteley_list.html', {'tipo' : 'ExpedienteLey'}, context_instance=RequestContext(request))
  File "/home/mmanto/virtualenvs3/python3.4/lib/python3.4/site-packages/django/shortcuts.py", line 50, in render
    return HttpResponse(loader.render_to_string(*args, **kwargs),
  File "/home/mmanto/virtualenvs3/python3.4/lib/python3.4/site-packages/django/template/loader.py", line 170, in render_to_string
    t = get_template(template_name, dirs)
  File "/home/mmanto/virtualenvs3/python3.4/lib/python3.4/site-packages/django/template/loader.py", line 144, in get_template
    template, origin = find_template(template_name, dirs)
  File "/home/mmanto/virtualenvs3/python3.4/lib/python3.4/site-packages/django/template/loader.py", line 132, in find_template
    source, display_name = loader(name, dirs)
  File "/home/mmanto/virtualenvs3/python3.4/lib/python3.4/site-packages/django/template/loader.py", line 44, in __call__
    return self.load_template(template_name, template_dirs)
  File "/home/mmanto/virtualenvs3/python3.4/lib/python3.4/site-packages/django/template/loader.py", line 50, in load_template
    template = get_template_from_string(source, origin, template_name)
  File "/home/mmanto/virtualenvs3/python3.4/lib/python3.4/site-packages/django/template/loader.py", line 156, in get_template_from_string
    return Template(source, origin, name)
  File "/home/mmanto/virtualenvs3/python3.4/lib/python3.4/site-packages/django/template/base.py", line 132, in __init__
    self.nodelist = compile_string(template_string, origin)
  File "/home/mmanto/virtualenvs3/python3.4/lib/python3.4/site-packages/django/template/base.py", line 162, in compile_string
    return parser.parse()
  File "/home/mmanto/virtualenvs3/python3.4/lib/python3.4/site-packages/django/template/base.py", line 290, in parse
    compiled_result = compile_func(self, token)
  File "/home/mmanto/virtualenvs3/python3.4/lib/python3.4/site-packages/django/template/loader_tags.py", line 201, in do_extends
    nodelist = parser.parse()
  File "/home/mmanto/virtualenvs3/python3.4/lib/python3.4/site-packages/django/template/base.py", line 290, in parse
    compiled_result = compile_func(self, token)
  File "/home/mmanto/virtualenvs3/python3.4/lib/python3.4/site-packages/django/template/loader_tags.py", line 175, in do_block
    nodelist = parser.parse(('endblock',))
  File "/home/mmanto/virtualenvs3/python3.4/lib/python3.4/site-packages/django/template/base.py", line 290, in parse
    compiled_result = compile_func(self, token)
  File "/home/mmanto/virtualenvs3/python3.4/lib/python3.4/site-packages/django/template/defaulttags.py", line 833, in do_for
    nodelist_loop = parser.parse(('empty', 'endfor',))
  File "/home/mmanto/virtualenvs3/python3.4/lib/python3.4/site-packages/django/template/base.py", line 290, in parse
    compiled_result = compile_func(self, token)
  File "/home/mmanto/virtualenvs3/python3.4/lib/python3.4/site-packages/django/template/defaulttags.py", line 975, in do_if
    nodelist = parser.parse(('elif', 'else', 'endif'))
  File "/home/mmanto/virtualenvs3/python3.4/lib/python3.4/site-packages/django/template/base.py", line 266, in parse
    filter_expression = self.compile_filter(token.contents)
  File "/home/mmanto/virtualenvs3/python3.4/lib/python3.4/site-packages/django/template/base.py", line 372, in compile_filter
    return FilterExpression(token, self)
  File "/home/mmanto/virtualenvs3/python3.4/lib/python3.4/site-packages/django/template/base.py", line 588, in __init__
    "from '%s'" % (token[upto:], token))
django.template.base.TemplateSyntaxError: Could not parse the remainder: ' tipo == 'ExpedienteLey' { Expediente Ley' from 'if tipo == 'ExpedienteLey' { Expediente Ley'
[06/May/2015 14:25:25] ERROR [django.request:231] Internal Server Error: /sig/expedientesLey/
Traceback (most recent call last):
  File "/home/mmanto/virtualenvs3/python3.4/lib/python3.4/site-packages/django/core/handlers/base.py", line 111, in get_response
    response = wrapped_callback(request, *callback_args, **callback_kwargs)
  File "/home/mmanto/virtualenvs3/python3.4/lib/python3.4/site-packages/django/contrib/auth/decorators.py", line 21, in _wrapped_view
    return view_func(request, *args, **kwargs)
  File "/home/mmanto/git/sstuv/documentos/views.py", line 90, in loadBusquedaExpedienteLey
    return render(request, 'expedienteley_list.html', {'tipo' : 'ExpedienteLey'}, context_instance=RequestContext(request))
  File "/home/mmanto/virtualenvs3/python3.4/lib/python3.4/site-packages/django/shortcuts.py", line 50, in render
    return HttpResponse(loader.render_to_string(*args, **kwargs),
  File "/home/mmanto/virtualenvs3/python3.4/lib/python3.4/site-packages/django/template/loader.py", line 170, in render_to_string
    t = get_template(template_name, dirs)
  File "/home/mmanto/virtualenvs3/python3.4/lib/python3.4/site-packages/django/template/loader.py", line 144, in get_template
    template, origin = find_template(template_name, dirs)
  File "/home/mmanto/virtualenvs3/python3.4/lib/python3.4/site-packages/django/template/loader.py", line 132, in find_template
    source, display_name = loader(name, dirs)
  File "/home/mmanto/virtualenvs3/python3.4/lib/python3.4/site-packages/django/template/loader.py", line 44, in __call__
    return self.load_template(template_name, template_dirs)
  File "/home/mmanto/virtualenvs3/python3.4/lib/python3.4/site-packages/django/template/loader.py", line 50, in load_template
    template = get_template_from_string(source, origin, template_name)
  File "/home/mmanto/virtualenvs3/python3.4/lib/python3.4/site-packages/django/template/loader.py", line 156, in get_template_from_string
    return Template(source, origin, name)
  File "/home/mmanto/virtualenvs3/python3.4/lib/python3.4/site-packages/django/template/base.py", line 132, in __init__
    self.nodelist = compile_string(template_string, origin)
  File "/home/mmanto/virtualenvs3/python3.4/lib/python3.4/site-packages/django/template/base.py", line 162, in compile_string
    return parser.parse()
  File "/home/mmanto/virtualenvs3/python3.4/lib/python3.4/site-packages/django/template/base.py", line 290, in parse
    compiled_result = compile_func(self, token)
  File "/home/mmanto/virtualenvs3/python3.4/lib/python3.4/site-packages/django/template/loader_tags.py", line 201, in do_extends
    nodelist = parser.parse()
  File "/home/mmanto/virtualenvs3/python3.4/lib/python3.4/site-packages/django/template/base.py", line 290, in parse
    compiled_result = compile_func(self, token)
  File "/home/mmanto/virtualenvs3/python3.4/lib/python3.4/site-packages/django/template/loader_tags.py", line 175, in do_block
    nodelist = parser.parse(('endblock',))
  File "/home/mmanto/virtualenvs3/python3.4/lib/python3.4/site-packages/django/template/base.py", line 290, in parse
    compiled_result = compile_func(self, token)
  File "/home/mmanto/virtualenvs3/python3.4/lib/python3.4/site-packages/django/template/defaulttags.py", line 833, in do_for
    nodelist_loop = parser.parse(('empty', 'endfor',))
  File "/home/mmanto/virtualenvs3/python3.4/lib/python3.4/site-packages/django/template/base.py", line 290, in parse
    compiled_result = compile_func(self, token)
  File "/home/mmanto/virtualenvs3/python3.4/lib/python3.4/site-packages/django/template/defaulttags.py", line 975, in do_if
    nodelist = parser.parse(('elif', 'else', 'endif'))
  File "/home/mmanto/virtualenvs3/python3.4/lib/python3.4/site-packages/django/template/base.py", line 266, in parse
    filter_expression = self.compile_filter(token.contents)
  File "/home/mmanto/virtualenvs3/python3.4/lib/python3.4/site-packages/django/template/base.py", line 372, in compile_filter
    return FilterExpression(token, self)
  File "/home/mmanto/virtualenvs3/python3.4/lib/python3.4/site-packages/django/template/base.py", line 588, in __init__
    "from '%s'" % (token[upto:], token))
django.template.base.TemplateSyntaxError: Could not parse the remainder: '%  if tipo == 'ExpedienteLey' %' from '%  if tipo == 'ExpedienteLey' %'
[06/May/2015 14:26:36] ERROR [django.request:231] Internal Server Error: /sig/expedientesLey/
Traceback (most recent call last):
  File "/home/mmanto/virtualenvs3/python3.4/lib/python3.4/site-packages/django/core/handlers/base.py", line 111, in get_response
    response = wrapped_callback(request, *callback_args, **callback_kwargs)
  File "/home/mmanto/virtualenvs3/python3.4/lib/python3.4/site-packages/django/contrib/auth/decorators.py", line 21, in _wrapped_view
    return view_func(request, *args, **kwargs)
  File "/home/mmanto/git/sstuv/documentos/views.py", line 90, in loadBusquedaExpedienteLey
    return render(request, 'expedienteley_list.html', {'tipo' : 'ExpedienteLey'}, context_instance=RequestContext(request))
  File "/home/mmanto/virtualenvs3/python3.4/lib/python3.4/site-packages/django/shortcuts.py", line 50, in render
    return HttpResponse(loader.render_to_string(*args, **kwargs),
  File "/home/mmanto/virtualenvs3/python3.4/lib/python3.4/site-packages/django/template/loader.py", line 170, in render_to_string
    t = get_template(template_name, dirs)
  File "/home/mmanto/virtualenvs3/python3.4/lib/python3.4/site-packages/django/template/loader.py", line 144, in get_template
    template, origin = find_template(template_name, dirs)
  File "/home/mmanto/virtualenvs3/python3.4/lib/python3.4/site-packages/django/template/loader.py", line 132, in find_template
    source, display_name = loader(name, dirs)
  File "/home/mmanto/virtualenvs3/python3.4/lib/python3.4/site-packages/django/template/loader.py", line 44, in __call__
    return self.load_template(template_name, template_dirs)
  File "/home/mmanto/virtualenvs3/python3.4/lib/python3.4/site-packages/django/template/loader.py", line 50, in load_template
    template = get_template_from_string(source, origin, template_name)
  File "/home/mmanto/virtualenvs3/python3.4/lib/python3.4/site-packages/django/template/loader.py", line 156, in get_template_from_string
    return Template(source, origin, name)
  File "/home/mmanto/virtualenvs3/python3.4/lib/python3.4/site-packages/django/template/base.py", line 132, in __init__
    self.nodelist = compile_string(template_string, origin)
  File "/home/mmanto/virtualenvs3/python3.4/lib/python3.4/site-packages/django/template/base.py", line 162, in compile_string
    return parser.parse()
  File "/home/mmanto/virtualenvs3/python3.4/lib/python3.4/site-packages/django/template/base.py", line 290, in parse
    compiled_result = compile_func(self, token)
  File "/home/mmanto/virtualenvs3/python3.4/lib/python3.4/site-packages/django/template/loader_tags.py", line 201, in do_extends
    nodelist = parser.parse()
  File "/home/mmanto/virtualenvs3/python3.4/lib/python3.4/site-packages/django/template/base.py", line 290, in parse
    compiled_result = compile_func(self, token)
  File "/home/mmanto/virtualenvs3/python3.4/lib/python3.4/site-packages/django/template/loader_tags.py", line 175, in do_block
    nodelist = parser.parse(('endblock',))
  File "/home/mmanto/virtualenvs3/python3.4/lib/python3.4/site-packages/django/template/base.py", line 290, in parse
    compiled_result = compile_func(self, token)
  File "/home/mmanto/virtualenvs3/python3.4/lib/python3.4/site-packages/django/template/defaulttags.py", line 833, in do_for
    nodelist_loop = parser.parse(('empty', 'endfor',))
  File "/home/mmanto/virtualenvs3/python3.4/lib/python3.4/site-packages/django/template/base.py", line 290, in parse
    compiled_result = compile_func(self, token)
  File "/home/mmanto/virtualenvs3/python3.4/lib/python3.4/site-packages/django/template/defaulttags.py", line 975, in do_if
    nodelist = parser.parse(('elif', 'else', 'endif'))
  File "/home/mmanto/virtualenvs3/python3.4/lib/python3.4/site-packages/django/template/base.py", line 266, in parse
    filter_expression = self.compile_filter(token.contents)
  File "/home/mmanto/virtualenvs3/python3.4/lib/python3.4/site-packages/django/template/base.py", line 372, in compile_filter
    return FilterExpression(token, self)
  File "/home/mmanto/virtualenvs3/python3.4/lib/python3.4/site-packages/django/template/base.py", line 588, in __init__
    "from '%s'" % (token[upto:], token))
django.template.base.TemplateSyntaxError: Could not parse the remainder: '%  if tipo == 'ExpedienteLey' %' from '%  if tipo == 'ExpedienteLey' %'
[06/May/2015 14:26:39] ERROR [django.request:231] Internal Server Error: /sig/expedientesLey/
Traceback (most recent call last):
  File "/home/mmanto/virtualenvs3/python3.4/lib/python3.4/site-packages/django/core/handlers/base.py", line 111, in get_response
    response = wrapped_callback(request, *callback_args, **callback_kwargs)
  File "/home/mmanto/virtualenvs3/python3.4/lib/python3.4/site-packages/django/contrib/auth/decorators.py", line 21, in _wrapped_view
    return view_func(request, *args, **kwargs)
  File "/home/mmanto/git/sstuv/documentos/views.py", line 90, in loadBusquedaExpedienteLey
    return render(request, 'expedienteley_list.html', {'tipo' : 'ExpedienteLey'}, context_instance=RequestContext(request))
  File "/home/mmanto/virtualenvs3/python3.4/lib/python3.4/site-packages/django/shortcuts.py", line 50, in render
    return HttpResponse(loader.render_to_string(*args, **kwargs),
  File "/home/mmanto/virtualenvs3/python3.4/lib/python3.4/site-packages/django/template/loader.py", line 170, in render_to_string
    t = get_template(template_name, dirs)
  File "/home/mmanto/virtualenvs3/python3.4/lib/python3.4/site-packages/django/template/loader.py", line 144, in get_template
    template, origin = find_template(template_name, dirs)
  File "/home/mmanto/virtualenvs3/python3.4/lib/python3.4/site-packages/django/template/loader.py", line 132, in find_template
    source, display_name = loader(name, dirs)
  File "/home/mmanto/virtualenvs3/python3.4/lib/python3.4/site-packages/django/template/loader.py", line 44, in __call__
    return self.load_template(template_name, template_dirs)
  File "/home/mmanto/virtualenvs3/python3.4/lib/python3.4/site-packages/django/template/loader.py", line 50, in load_template
    template = get_template_from_string(source, origin, template_name)
  File "/home/mmanto/virtualenvs3/python3.4/lib/python3.4/site-packages/django/template/loader.py", line 156, in get_template_from_string
    return Template(source, origin, name)
  File "/home/mmanto/virtualenvs3/python3.4/lib/python3.4/site-packages/django/template/base.py", line 132, in __init__
    self.nodelist = compile_string(template_string, origin)
  File "/home/mmanto/virtualenvs3/python3.4/lib/python3.4/site-packages/django/template/base.py", line 162, in compile_string
    return parser.parse()
  File "/home/mmanto/virtualenvs3/python3.4/lib/python3.4/site-packages/django/template/base.py", line 290, in parse
    compiled_result = compile_func(self, token)
  File "/home/mmanto/virtualenvs3/python3.4/lib/python3.4/site-packages/django/template/loader_tags.py", line 201, in do_extends
    nodelist = parser.parse()
  File "/home/mmanto/virtualenvs3/python3.4/lib/python3.4/site-packages/django/template/base.py", line 290, in parse
    compiled_result = compile_func(self, token)
  File "/home/mmanto/virtualenvs3/python3.4/lib/python3.4/site-packages/django/template/loader_tags.py", line 175, in do_block
    nodelist = parser.parse(('endblock',))
  File "/home/mmanto/virtualenvs3/python3.4/lib/python3.4/site-packages/django/template/base.py", line 290, in parse
    compiled_result = compile_func(self, token)
  File "/home/mmanto/virtualenvs3/python3.4/lib/python3.4/site-packages/django/template/defaulttags.py", line 833, in do_for
    nodelist_loop = parser.parse(('empty', 'endfor',))
  File "/home/mmanto/virtualenvs3/python3.4/lib/python3.4/site-packages/django/template/base.py", line 290, in parse
    compiled_result = compile_func(self, token)
  File "/home/mmanto/virtualenvs3/python3.4/lib/python3.4/site-packages/django/template/defaulttags.py", line 975, in do_if
    nodelist = parser.parse(('elif', 'else', 'endif'))
  File "/home/mmanto/virtualenvs3/python3.4/lib/python3.4/site-packages/django/template/base.py", line 266, in parse
    filter_expression = self.compile_filter(token.contents)
  File "/home/mmanto/virtualenvs3/python3.4/lib/python3.4/site-packages/django/template/base.py", line 372, in compile_filter
    return FilterExpression(token, self)
  File "/home/mmanto/virtualenvs3/python3.4/lib/python3.4/site-packages/django/template/base.py", line 588, in __init__
    "from '%s'" % (token[upto:], token))
django.template.base.TemplateSyntaxError: Could not parse the remainder: '%  if tipo == 'ExpedienteLey' %' from '%  if tipo == 'ExpedienteLey' %'
[06/May/2015 14:26:52] ERROR [django.request:231] Internal Server Error: /sig/expedientesLey/
Traceback (most recent call last):
  File "/home/mmanto/virtualenvs3/python3.4/lib/python3.4/site-packages/django/core/handlers/base.py", line 111, in get_response
    response = wrapped_callback(request, *callback_args, **callback_kwargs)
  File "/home/mmanto/virtualenvs3/python3.4/lib/python3.4/site-packages/django/contrib/auth/decorators.py", line 21, in _wrapped_view
    return view_func(request, *args, **kwargs)
  File "/home/mmanto/git/sstuv/documentos/views.py", line 90, in loadBusquedaExpedienteLey
    return render(request, 'expedienteley_list.html', {'tipo' : 'ExpedienteLey'}, context_instance=RequestContext(request))
  File "/home/mmanto/virtualenvs3/python3.4/lib/python3.4/site-packages/django/shortcuts.py", line 50, in render
    return HttpResponse(loader.render_to_string(*args, **kwargs),
  File "/home/mmanto/virtualenvs3/python3.4/lib/python3.4/site-packages/django/template/loader.py", line 170, in render_to_string
    t = get_template(template_name, dirs)
  File "/home/mmanto/virtualenvs3/python3.4/lib/python3.4/site-packages/django/template/loader.py", line 144, in get_template
    template, origin = find_template(template_name, dirs)
  File "/home/mmanto/virtualenvs3/python3.4/lib/python3.4/site-packages/django/template/loader.py", line 132, in find_template
    source, display_name = loader(name, dirs)
  File "/home/mmanto/virtualenvs3/python3.4/lib/python3.4/site-packages/django/template/loader.py", line 44, in __call__
    return self.load_template(template_name, template_dirs)
  File "/home/mmanto/virtualenvs3/python3.4/lib/python3.4/site-packages/django/template/loader.py", line 50, in load_template
    template = get_template_from_string(source, origin, template_name)
  File "/home/mmanto/virtualenvs3/python3.4/lib/python3.4/site-packages/django/template/loader.py", line 156, in get_template_from_string
    return Template(source, origin, name)
  File "/home/mmanto/virtualenvs3/python3.4/lib/python3.4/site-packages/django/template/base.py", line 132, in __init__
    self.nodelist = compile_string(template_string, origin)
  File "/home/mmanto/virtualenvs3/python3.4/lib/python3.4/site-packages/django/template/base.py", line 162, in compile_string
    return parser.parse()
  File "/home/mmanto/virtualenvs3/python3.4/lib/python3.4/site-packages/django/template/base.py", line 290, in parse
    compiled_result = compile_func(self, token)
  File "/home/mmanto/virtualenvs3/python3.4/lib/python3.4/site-packages/django/template/loader_tags.py", line 201, in do_extends
    nodelist = parser.parse()
  File "/home/mmanto/virtualenvs3/python3.4/lib/python3.4/site-packages/django/template/base.py", line 290, in parse
    compiled_result = compile_func(self, token)
  File "/home/mmanto/virtualenvs3/python3.4/lib/python3.4/site-packages/django/template/loader_tags.py", line 175, in do_block
    nodelist = parser.parse(('endblock',))
  File "/home/mmanto/virtualenvs3/python3.4/lib/python3.4/site-packages/django/template/base.py", line 290, in parse
    compiled_result = compile_func(self, token)
  File "/home/mmanto/virtualenvs3/python3.4/lib/python3.4/site-packages/django/template/defaulttags.py", line 833, in do_for
    nodelist_loop = parser.parse(('empty', 'endfor',))
  File "/home/mmanto/virtualenvs3/python3.4/lib/python3.4/site-packages/django/template/base.py", line 290, in parse
    compiled_result = compile_func(self, token)
  File "/home/mmanto/virtualenvs3/python3.4/lib/python3.4/site-packages/django/template/defaulttags.py", line 975, in do_if
    nodelist = parser.parse(('elif', 'else', 'endif'))
  File "/home/mmanto/virtualenvs3/python3.4/lib/python3.4/site-packages/django/template/base.py", line 266, in parse
    filter_expression = self.compile_filter(token.contents)
  File "/home/mmanto/virtualenvs3/python3.4/lib/python3.4/site-packages/django/template/base.py", line 372, in compile_filter
    return FilterExpression(token, self)
  File "/home/mmanto/virtualenvs3/python3.4/lib/python3.4/site-packages/django/template/base.py", line 588, in __init__
    "from '%s'" % (token[upto:], token))
django.template.base.TemplateSyntaxError: Could not parse the remainder: '%  if tipo == 'ExpedienteLey' %' from '%  if tipo == 'ExpedienteLey' %'
[06/May/2015 14:26:54] ERROR [django.request:231] Internal Server Error: /sig/expedientesLey/
Traceback (most recent call last):
  File "/home/mmanto/virtualenvs3/python3.4/lib/python3.4/site-packages/django/core/handlers/base.py", line 111, in get_response
    response = wrapped_callback(request, *callback_args, **callback_kwargs)
  File "/home/mmanto/virtualenvs3/python3.4/lib/python3.4/site-packages/django/contrib/auth/decorators.py", line 21, in _wrapped_view
    return view_func(request, *args, **kwargs)
  File "/home/mmanto/git/sstuv/documentos/views.py", line 90, in loadBusquedaExpedienteLey
    return render(request, 'expedienteley_list.html', {'tipo' : 'ExpedienteLey'}, context_instance=RequestContext(request))
  File "/home/mmanto/virtualenvs3/python3.4/lib/python3.4/site-packages/django/shortcuts.py", line 50, in render
    return HttpResponse(loader.render_to_string(*args, **kwargs),
  File "/home/mmanto/virtualenvs3/python3.4/lib/python3.4/site-packages/django/template/loader.py", line 170, in render_to_string
    t = get_template(template_name, dirs)
  File "/home/mmanto/virtualenvs3/python3.4/lib/python3.4/site-packages/django/template/loader.py", line 144, in get_template
    template, origin = find_template(template_name, dirs)
  File "/home/mmanto/virtualenvs3/python3.4/lib/python3.4/site-packages/django/template/loader.py", line 132, in find_template
    source, display_name = loader(name, dirs)
  File "/home/mmanto/virtualenvs3/python3.4/lib/python3.4/site-packages/django/template/loader.py", line 44, in __call__
    return self.load_template(template_name, template_dirs)
  File "/home/mmanto/virtualenvs3/python3.4/lib/python3.4/site-packages/django/template/loader.py", line 50, in load_template
    template = get_template_from_string(source, origin, template_name)
  File "/home/mmanto/virtualenvs3/python3.4/lib/python3.4/site-packages/django/template/loader.py", line 156, in get_template_from_string
    return Template(source, origin, name)
  File "/home/mmanto/virtualenvs3/python3.4/lib/python3.4/site-packages/django/template/base.py", line 132, in __init__
    self.nodelist = compile_string(template_string, origin)
  File "/home/mmanto/virtualenvs3/python3.4/lib/python3.4/site-packages/django/template/base.py", line 162, in compile_string
    return parser.parse()
  File "/home/mmanto/virtualenvs3/python3.4/lib/python3.4/site-packages/django/template/base.py", line 290, in parse
    compiled_result = compile_func(self, token)
  File "/home/mmanto/virtualenvs3/python3.4/lib/python3.4/site-packages/django/template/loader_tags.py", line 201, in do_extends
    nodelist = parser.parse()
  File "/home/mmanto/virtualenvs3/python3.4/lib/python3.4/site-packages/django/template/base.py", line 290, in parse
    compiled_result = compile_func(self, token)
  File "/home/mmanto/virtualenvs3/python3.4/lib/python3.4/site-packages/django/template/loader_tags.py", line 175, in do_block
    nodelist = parser.parse(('endblock',))
  File "/home/mmanto/virtualenvs3/python3.4/lib/python3.4/site-packages/django/template/base.py", line 290, in parse
    compiled_result = compile_func(self, token)
  File "/home/mmanto/virtualenvs3/python3.4/lib/python3.4/site-packages/django/template/defaulttags.py", line 833, in do_for
    nodelist_loop = parser.parse(('empty', 'endfor',))
  File "/home/mmanto/virtualenvs3/python3.4/lib/python3.4/site-packages/django/template/base.py", line 290, in parse
    compiled_result = compile_func(self, token)
  File "/home/mmanto/virtualenvs3/python3.4/lib/python3.4/site-packages/django/template/defaulttags.py", line 975, in do_if
    nodelist = parser.parse(('elif', 'else', 'endif'))
  File "/home/mmanto/virtualenvs3/python3.4/lib/python3.4/site-packages/django/template/base.py", line 266, in parse
    filter_expression = self.compile_filter(token.contents)
  File "/home/mmanto/virtualenvs3/python3.4/lib/python3.4/site-packages/django/template/base.py", line 372, in compile_filter
    return FilterExpression(token, self)
  File "/home/mmanto/virtualenvs3/python3.4/lib/python3.4/site-packages/django/template/base.py", line 588, in __init__
    "from '%s'" % (token[upto:], token))
django.template.base.TemplateSyntaxError: Could not parse the remainder: '%  if tipo == 'ExpedienteLey' %' from '%  if tipo == 'ExpedienteLey' %'
[06/May/2015 14:28:03] ERROR [django.request:231] Internal Server Error: /sig/expedientesLey/
Traceback (most recent call last):
  File "/home/mmanto/virtualenvs3/python3.4/lib/python3.4/site-packages/django/core/handlers/base.py", line 111, in get_response
    response = wrapped_callback(request, *callback_args, **callback_kwargs)
  File "/home/mmanto/virtualenvs3/python3.4/lib/python3.4/site-packages/django/contrib/auth/decorators.py", line 21, in _wrapped_view
    return view_func(request, *args, **kwargs)
  File "/home/mmanto/git/sstuv/documentos/views.py", line 90, in loadBusquedaExpedienteLey
    return render(request, 'expedienteley_list.html', {'tipo' : 'ExpedienteLey'}, context_instance=RequestContext(request))
  File "/home/mmanto/virtualenvs3/python3.4/lib/python3.4/site-packages/django/shortcuts.py", line 50, in render
    return HttpResponse(loader.render_to_string(*args, **kwargs),
  File "/home/mmanto/virtualenvs3/python3.4/lib/python3.4/site-packages/django/template/loader.py", line 170, in render_to_string
    t = get_template(template_name, dirs)
  File "/home/mmanto/virtualenvs3/python3.4/lib/python3.4/site-packages/django/template/loader.py", line 144, in get_template
    template, origin = find_template(template_name, dirs)
  File "/home/mmanto/virtualenvs3/python3.4/lib/python3.4/site-packages/django/template/loader.py", line 132, in find_template
    source, display_name = loader(name, dirs)
  File "/home/mmanto/virtualenvs3/python3.4/lib/python3.4/site-packages/django/template/loader.py", line 44, in __call__
    return self.load_template(template_name, template_dirs)
  File "/home/mmanto/virtualenvs3/python3.4/lib/python3.4/site-packages/django/template/loader.py", line 50, in load_template
    template = get_template_from_string(source, origin, template_name)
  File "/home/mmanto/virtualenvs3/python3.4/lib/python3.4/site-packages/django/template/loader.py", line 156, in get_template_from_string
    return Template(source, origin, name)
  File "/home/mmanto/virtualenvs3/python3.4/lib/python3.4/site-packages/django/template/base.py", line 132, in __init__
    self.nodelist = compile_string(template_string, origin)
  File "/home/mmanto/virtualenvs3/python3.4/lib/python3.4/site-packages/django/template/base.py", line 162, in compile_string
    return parser.parse()
  File "/home/mmanto/virtualenvs3/python3.4/lib/python3.4/site-packages/django/template/base.py", line 290, in parse
    compiled_result = compile_func(self, token)
  File "/home/mmanto/virtualenvs3/python3.4/lib/python3.4/site-packages/django/template/loader_tags.py", line 201, in do_extends
    nodelist = parser.parse()
  File "/home/mmanto/virtualenvs3/python3.4/lib/python3.4/site-packages/django/template/base.py", line 290, in parse
    compiled_result = compile_func(self, token)
  File "/home/mmanto/virtualenvs3/python3.4/lib/python3.4/site-packages/django/template/loader_tags.py", line 175, in do_block
    nodelist = parser.parse(('endblock',))
  File "/home/mmanto/virtualenvs3/python3.4/lib/python3.4/site-packages/django/template/base.py", line 290, in parse
    compiled_result = compile_func(self, token)
  File "/home/mmanto/virtualenvs3/python3.4/lib/python3.4/site-packages/django/template/defaulttags.py", line 833, in do_for
    nodelist_loop = parser.parse(('empty', 'endfor',))
  File "/home/mmanto/virtualenvs3/python3.4/lib/python3.4/site-packages/django/template/base.py", line 290, in parse
    compiled_result = compile_func(self, token)
  File "/home/mmanto/virtualenvs3/python3.4/lib/python3.4/site-packages/django/template/defaulttags.py", line 975, in do_if
    nodelist = parser.parse(('elif', 'else', 'endif'))
  File "/home/mmanto/virtualenvs3/python3.4/lib/python3.4/site-packages/django/template/base.py", line 266, in parse
    filter_expression = self.compile_filter(token.contents)
  File "/home/mmanto/virtualenvs3/python3.4/lib/python3.4/site-packages/django/template/base.py", line 372, in compile_filter
    return FilterExpression(token, self)
  File "/home/mmanto/virtualenvs3/python3.4/lib/python3.4/site-packages/django/template/base.py", line 588, in __init__
    "from '%s'" % (token[upto:], token))
django.template.base.TemplateSyntaxError: Could not parse the remainder: '%  if tipo == 'ExpedienteLey' %' from '%  if tipo == 'ExpedienteLey' %'
[06/May/2015 14:28:05] ERROR [django.request:231] Internal Server Error: /sig/expedientesLey/
Traceback (most recent call last):
  File "/home/mmanto/virtualenvs3/python3.4/lib/python3.4/site-packages/django/core/handlers/base.py", line 111, in get_response
    response = wrapped_callback(request, *callback_args, **callback_kwargs)
  File "/home/mmanto/virtualenvs3/python3.4/lib/python3.4/site-packages/django/contrib/auth/decorators.py", line 21, in _wrapped_view
    return view_func(request, *args, **kwargs)
  File "/home/mmanto/git/sstuv/documentos/views.py", line 90, in loadBusquedaExpedienteLey
    return render(request, 'expedienteley_list.html', {'tipo' : 'ExpedienteLey'}, context_instance=RequestContext(request))
  File "/home/mmanto/virtualenvs3/python3.4/lib/python3.4/site-packages/django/shortcuts.py", line 50, in render
    return HttpResponse(loader.render_to_string(*args, **kwargs),
  File "/home/mmanto/virtualenvs3/python3.4/lib/python3.4/site-packages/django/template/loader.py", line 170, in render_to_string
    t = get_template(template_name, dirs)
  File "/home/mmanto/virtualenvs3/python3.4/lib/python3.4/site-packages/django/template/loader.py", line 144, in get_template
    template, origin = find_template(template_name, dirs)
  File "/home/mmanto/virtualenvs3/python3.4/lib/python3.4/site-packages/django/template/loader.py", line 132, in find_template
    source, display_name = loader(name, dirs)
  File "/home/mmanto/virtualenvs3/python3.4/lib/python3.4/site-packages/django/template/loader.py", line 44, in __call__
    return self.load_template(template_name, template_dirs)
  File "/home/mmanto/virtualenvs3/python3.4/lib/python3.4/site-packages/django/template/loader.py", line 50, in load_template
    template = get_template_from_string(source, origin, template_name)
  File "/home/mmanto/virtualenvs3/python3.4/lib/python3.4/site-packages/django/template/loader.py", line 156, in get_template_from_string
    return Template(source, origin, name)
  File "/home/mmanto/virtualenvs3/python3.4/lib/python3.4/site-packages/django/template/base.py", line 132, in __init__
    self.nodelist = compile_string(template_string, origin)
  File "/home/mmanto/virtualenvs3/python3.4/lib/python3.4/site-packages/django/template/base.py", line 162, in compile_string
    return parser.parse()
  File "/home/mmanto/virtualenvs3/python3.4/lib/python3.4/site-packages/django/template/base.py", line 290, in parse
    compiled_result = compile_func(self, token)
  File "/home/mmanto/virtualenvs3/python3.4/lib/python3.4/site-packages/django/template/loader_tags.py", line 201, in do_extends
    nodelist = parser.parse()
  File "/home/mmanto/virtualenvs3/python3.4/lib/python3.4/site-packages/django/template/base.py", line 290, in parse
    compiled_result = compile_func(self, token)
  File "/home/mmanto/virtualenvs3/python3.4/lib/python3.4/site-packages/django/template/loader_tags.py", line 175, in do_block
    nodelist = parser.parse(('endblock',))
  File "/home/mmanto/virtualenvs3/python3.4/lib/python3.4/site-packages/django/template/base.py", line 290, in parse
    compiled_result = compile_func(self, token)
  File "/home/mmanto/virtualenvs3/python3.4/lib/python3.4/site-packages/django/template/defaulttags.py", line 833, in do_for
    nodelist_loop = parser.parse(('empty', 'endfor',))
  File "/home/mmanto/virtualenvs3/python3.4/lib/python3.4/site-packages/django/template/base.py", line 290, in parse
    compiled_result = compile_func(self, token)
  File "/home/mmanto/virtualenvs3/python3.4/lib/python3.4/site-packages/django/template/defaulttags.py", line 975, in do_if
    nodelist = parser.parse(('elif', 'else', 'endif'))
  File "/home/mmanto/virtualenvs3/python3.4/lib/python3.4/site-packages/django/template/base.py", line 266, in parse
    filter_expression = self.compile_filter(token.contents)
  File "/home/mmanto/virtualenvs3/python3.4/lib/python3.4/site-packages/django/template/base.py", line 372, in compile_filter
    return FilterExpression(token, self)
  File "/home/mmanto/virtualenvs3/python3.4/lib/python3.4/site-packages/django/template/base.py", line 588, in __init__
    "from '%s'" % (token[upto:], token))
django.template.base.TemplateSyntaxError: Could not parse the remainder: '%  if tipo == 'ExpedienteLey' %' from '%  if tipo == 'ExpedienteLey' %'
[06/May/2015 14:33:37] INFO [sstuvInfo:84] busqueda de expedientes en logger info
[06/May/2015 14:33:45] INFO [sstuvInfo:84] busqueda de expedientes en logger info
[06/May/2015 14:35:27] ERROR [django.request:231] Internal Server Error: /sig/expedientes/guardar/
Traceback (most recent call last):
  File "/home/mmanto/virtualenvs3/python3.4/lib/python3.4/site-packages/django/core/handlers/base.py", line 111, in get_response
    response = wrapped_callback(request, *callback_args, **callback_kwargs)
  File "/home/mmanto/virtualenvs3/python3.4/lib/python3.4/site-packages/django/contrib/auth/decorators.py", line 21, in _wrapped_view
    return view_func(request, *args, **kwargs)
  File "/home/mmanto/git/sstuv/documentos/views.py", line 198, in saveExpediente
    expediente.fecha = datetime.strptime(request.POST.get('fecha'), "%d/%m/%Y")  # datetime.strptime( fecha, "%M/%d/%Y" )
  File "/usr/lib/python3.4/_strptime.py", line 500, in _strptime_datetime
    tt, fraction = _strptime(data_string, format)
  File "/usr/lib/python3.4/_strptime.py", line 337, in _strptime
    (data_string, format))
ValueError: time data '6 Mayo 2015' does not match format '%d/%m/%Y'
[06/May/2015 14:35:48] INFO [sstuvInfo:84] busqueda de expedientes en logger info
[06/May/2015 14:35:56] INFO [sstuvInfo:84] busqueda de expedientes en logger info
[06/May/2015 14:36:11] INFO [sstuvInfo:84] busqueda de expedientes en logger info
[06/May/2015 14:36:11] INFO [sstuvInfo:84] busqueda de expedientes en logger info
[06/May/2015 14:36:16] INFO [sstuvInfo:84] busqueda de expedientes en logger info
[06/May/2015 14:36:18] INFO [sstuvInfo:84] busqueda de expedientes en logger info
[06/May/2015 14:36:18] INFO [sstuvInfo:84] busqueda de expedientes en logger info
[06/May/2015 14:36:33] INFO [sstuvInfo:84] busqueda de expedientes en logger info
[06/May/2015 14:36:53] INFO [sstuvInfo:84] busqueda de expedientes en logger info
[06/May/2015 14:39:46] INFO [sstuvInfo:84] busqueda de expedientes en logger info
[06/May/2015 14:44:52] INFO [sstuvInfo:84] busqueda de expedientes en logger info
[06/May/2015 15:00:39] INFO [sstuvInfo:84] busqueda de expedientes en logger info
[06/May/2015 15:01:12] INFO [sstuvInfo:84] busqueda de expedientes en logger info
[06/May/2015 15:16:53] ERROR [django.request:231] Internal Server Error: /sig/expediente/inspeccionar/Expediente/2423/33333333/2025/0/0/0/
Traceback (most recent call last):
  File "/home/mmanto/virtualenvs3/python3.4/lib/python3.4/site-packages/django/template/smartif.py", line 173, in translate_token
    op = OPERATORS[token]
KeyError: '{{'

During handling of the above exception, another exception occurred:

Traceback (most recent call last):
  File "/home/mmanto/virtualenvs3/python3.4/lib/python3.4/site-packages/django/core/handlers/base.py", line 111, in get_response
    response = wrapped_callback(request, *callback_args, **callback_kwargs)
  File "/home/mmanto/virtualenvs3/python3.4/lib/python3.4/site-packages/django/contrib/auth/decorators.py", line 21, in _wrapped_view
    return view_func(request, *args, **kwargs)
  File "/home/mmanto/git/sstuv/documentos/views.py", line 73, in showExpediente
    return render(request, 'expediente_ley.html', {'expediente': expediente, 'partidos': partidos, 'departamentosInternos':departamentosInternos, 'departamentosExternos':departamentosExternos, 'tipo':tipo, 'accion':'editar', 'pases':pases, 'organismoFiltro' : organismo, 'numeroFiltro': numero, 'fecha_inicioFiltro' :fecha_inicio, 'departamento_origen' : departamento_origen }, context_instance=RequestContext(request))
  File "/home/mmanto/virtualenvs3/python3.4/lib/python3.4/site-packages/django/shortcuts.py", line 50, in render
    return HttpResponse(loader.render_to_string(*args, **kwargs),
  File "/home/mmanto/virtualenvs3/python3.4/lib/python3.4/site-packages/django/template/loader.py", line 170, in render_to_string
    t = get_template(template_name, dirs)
  File "/home/mmanto/virtualenvs3/python3.4/lib/python3.4/site-packages/django/template/loader.py", line 144, in get_template
    template, origin = find_template(template_name, dirs)
  File "/home/mmanto/virtualenvs3/python3.4/lib/python3.4/site-packages/django/template/loader.py", line 132, in find_template
    source, display_name = loader(name, dirs)
  File "/home/mmanto/virtualenvs3/python3.4/lib/python3.4/site-packages/django/template/loader.py", line 44, in __call__
    return self.load_template(template_name, template_dirs)
  File "/home/mmanto/virtualenvs3/python3.4/lib/python3.4/site-packages/django/template/loader.py", line 50, in load_template
    template = get_template_from_string(source, origin, template_name)
  File "/home/mmanto/virtualenvs3/python3.4/lib/python3.4/site-packages/django/template/loader.py", line 156, in get_template_from_string
    return Template(source, origin, name)
  File "/home/mmanto/virtualenvs3/python3.4/lib/python3.4/site-packages/django/template/base.py", line 132, in __init__
    self.nodelist = compile_string(template_string, origin)
  File "/home/mmanto/virtualenvs3/python3.4/lib/python3.4/site-packages/django/template/base.py", line 162, in compile_string
    return parser.parse()
  File "/home/mmanto/virtualenvs3/python3.4/lib/python3.4/site-packages/django/template/base.py", line 290, in parse
    compiled_result = compile_func(self, token)
  File "/home/mmanto/virtualenvs3/python3.4/lib/python3.4/site-packages/django/template/loader_tags.py", line 201, in do_extends
    nodelist = parser.parse()
  File "/home/mmanto/virtualenvs3/python3.4/lib/python3.4/site-packages/django/template/base.py", line 290, in parse
    compiled_result = compile_func(self, token)
  File "/home/mmanto/virtualenvs3/python3.4/lib/python3.4/site-packages/django/template/loader_tags.py", line 175, in do_block
    nodelist = parser.parse(('endblock',))
  File "/home/mmanto/virtualenvs3/python3.4/lib/python3.4/site-packages/django/template/base.py", line 290, in parse
    compiled_result = compile_func(self, token)
  File "/home/mmanto/virtualenvs3/python3.4/lib/python3.4/site-packages/django/template/defaulttags.py", line 974, in do_if
    condition = TemplateIfParser(parser, bits).parse()
  File "/home/mmanto/virtualenvs3/python3.4/lib/python3.4/site-packages/django/template/defaulttags.py", line 906, in __init__
    super(TemplateIfParser, self).__init__(*args, **kwargs)
  File "/home/mmanto/virtualenvs3/python3.4/lib/python3.4/site-packages/django/template/smartif.py", line 164, in __init__
    mapped_tokens.append(self.translate_token(token))
  File "/home/mmanto/virtualenvs3/python3.4/lib/python3.4/site-packages/django/template/smartif.py", line 175, in translate_token
    return self.create_var(token)
  File "/home/mmanto/virtualenvs3/python3.4/lib/python3.4/site-packages/django/template/defaulttags.py", line 909, in create_var
    return TemplateLiteral(self.template_parser.compile_filter(value), value)
  File "/home/mmanto/virtualenvs3/python3.4/lib/python3.4/site-packages/django/template/base.py", line 372, in compile_filter
    return FilterExpression(token, self)
  File "/home/mmanto/virtualenvs3/python3.4/lib/python3.4/site-packages/django/template/base.py", line 588, in __init__
    "from '%s'" % (token[upto:], token))
django.template.base.TemplateSyntaxError: Could not parse the remainder: '{{' from '{{'
[06/May/2015 15:35:02] ERROR [django.request:231] Internal Server Error: /sig/expediente/inspeccionar/Expediente/2423/33333333/2025/0/0/0/
Traceback (most recent call last):
  File "/home/mmanto/virtualenvs3/python3.4/lib/python3.4/site-packages/django/core/handlers/base.py", line 111, in get_response
    response = wrapped_callback(request, *callback_args, **callback_kwargs)
  File "/home/mmanto/virtualenvs3/python3.4/lib/python3.4/site-packages/django/contrib/auth/decorators.py", line 21, in _wrapped_view
    return view_func(request, *args, **kwargs)
  File "/home/mmanto/git/sstuv/documentos/views.py", line 72, in showExpediente
    proximo_pase_id = expediente.pase_set.last().id() + 1
TypeError: 'int' object is not callable
[06/May/2015 15:35:48] ERROR [django.request:231] Internal Server Error: /sig/expediente/inspeccionar/Expediente/2423/33333333/2025/0/0/0/
Traceback (most recent call last):
  File "/home/mmanto/virtualenvs3/python3.4/lib/python3.4/site-packages/django/core/handlers/base.py", line 111, in get_response
    response = wrapped_callback(request, *callback_args, **callback_kwargs)
  File "/home/mmanto/virtualenvs3/python3.4/lib/python3.4/site-packages/django/contrib/auth/decorators.py", line 21, in _wrapped_view
    return view_func(request, *args, **kwargs)
  File "/home/mmanto/git/sstuv/documentos/views.py", line 72, in showExpediente
    proximo_pase_id = expediente.pase_set.last().id() + 1
TypeError: 'int' object is not callable
[06/May/2015 15:35:51] ERROR [django.request:231] Internal Server Error: /sig/expediente/inspeccionar/Expediente/2423/33333333/2025/0/0/0/
Traceback (most recent call last):
  File "/home/mmanto/virtualenvs3/python3.4/lib/python3.4/site-packages/django/core/handlers/base.py", line 111, in get_response
    response = wrapped_callback(request, *callback_args, **callback_kwargs)
  File "/home/mmanto/virtualenvs3/python3.4/lib/python3.4/site-packages/django/contrib/auth/decorators.py", line 21, in _wrapped_view
    return view_func(request, *args, **kwargs)
  File "/home/mmanto/git/sstuv/documentos/views.py", line 72, in showExpediente
    proximo_pase_id = expediente.pase_set.last().id() + 1
TypeError: 'int' object is not callable
[06/May/2015 15:37:15] ERROR [django.request:231] Internal Server Error: /sig/expediente/inspeccionar/Expediente/2423/33333333/2025/0/0/0/
Traceback (most recent call last):
  File "/home/mmanto/virtualenvs3/python3.4/lib/python3.4/site-packages/django/core/handlers/base.py", line 111, in get_response
    response = wrapped_callback(request, *callback_args, **callback_kwargs)
  File "/home/mmanto/virtualenvs3/python3.4/lib/python3.4/site-packages/django/contrib/auth/decorators.py", line 21, in _wrapped_view
    return view_func(request, *args, **kwargs)
  File "/home/mmanto/git/sstuv/documentos/views.py", line 72, in showExpediente
    pase_id_actual = expediente.pase_set.last().id()
TypeError: 'int' object is not callable
[06/May/2015 15:37:17] ERROR [django.request:231] Internal Server Error: /sig/expediente/inspeccionar/Expediente/2423/33333333/2025/0/0/0/
Traceback (most recent call last):
  File "/home/mmanto/virtualenvs3/python3.4/lib/python3.4/site-packages/django/core/handlers/base.py", line 111, in get_response
    response = wrapped_callback(request, *callback_args, **callback_kwargs)
  File "/home/mmanto/virtualenvs3/python3.4/lib/python3.4/site-packages/django/contrib/auth/decorators.py", line 21, in _wrapped_view
    return view_func(request, *args, **kwargs)
  File "/home/mmanto/git/sstuv/documentos/views.py", line 72, in showExpediente
    pase_id_actual = expediente.pase_set.last().id()
TypeError: 'int' object is not callable
[06/May/2015 15:38:00] ERROR [django.request:231] Internal Server Error: /sig/expediente/inspeccionar/Expediente/2423/33333333/2025/0/0/0/
Traceback (most recent call last):
  File "/home/mmanto/virtualenvs3/python3.4/lib/python3.4/site-packages/django/core/handlers/base.py", line 111, in get_response
    response = wrapped_callback(request, *callback_args, **callback_kwargs)
  File "/home/mmanto/virtualenvs3/python3.4/lib/python3.4/site-packages/django/contrib/auth/decorators.py", line 21, in _wrapped_view
    return view_func(request, *args, **kwargs)
  File "/home/mmanto/git/sstuv/documentos/views.py", line 73, in showExpediente
    pase_id_actual = pase_id_actual + 1
TypeError: unsupported operand type(s) for +: 'Pase' and 'int'
[06/May/2015 15:38:41] ERROR [django.request:231] Internal Server Error: /sig/expediente/inspeccionar/Expediente/2423/33333333/2025/0/0/0/
Traceback (most recent call last):
  File "/home/mmanto/virtualenvs3/python3.4/lib/python3.4/site-packages/django/core/handlers/base.py", line 111, in get_response
    response = wrapped_callback(request, *callback_args, **callback_kwargs)
  File "/home/mmanto/virtualenvs3/python3.4/lib/python3.4/site-packages/django/contrib/auth/decorators.py", line 21, in _wrapped_view
    return view_func(request, *args, **kwargs)
  File "/home/mmanto/git/sstuv/documentos/views.py", line 74, in showExpediente
    pase_id_actual = pase_id_actual + 1
TypeError: unsupported operand type(s) for +: 'Pase' and 'int'
[06/May/2015 15:42:58] ERROR [django.request:231] Internal Server Error: /sig/expediente/inspeccionar/Expediente/2423/33333333/2025/0/0/0/
Traceback (most recent call last):
  File "/home/mmanto/virtualenvs3/python3.4/lib/python3.4/site-packages/django/core/handlers/base.py", line 111, in get_response
    response = wrapped_callback(request, *callback_args, **callback_kwargs)
  File "/home/mmanto/virtualenvs3/python3.4/lib/python3.4/site-packages/django/contrib/auth/decorators.py", line 21, in _wrapped_view
    return view_func(request, *args, **kwargs)
  File "/home/mmanto/git/sstuv/documentos/views.py", line 72, in showExpediente
    pase_id_actual = expediente.pase_set.last().id()
TypeError: 'int' object is not callable
[06/May/2015 15:44:38] ERROR [django.request:231] Internal Server Error: /sig/expediente/inspeccionar/Expediente/2423/33333333/2025/0/0/0/
Traceback (most recent call last):
  File "/home/mmanto/virtualenvs3/python3.4/lib/python3.4/site-packages/django/core/handlers/base.py", line 111, in get_response
    response = wrapped_callback(request, *callback_args, **callback_kwargs)
  File "/home/mmanto/virtualenvs3/python3.4/lib/python3.4/site-packages/django/contrib/auth/decorators.py", line 21, in _wrapped_view
    return view_func(request, *args, **kwargs)
  File "/home/mmanto/git/sstuv/documentos/views.py", line 77, in showExpediente
    return render(request, 'expediente_ley.html', {'expediente': expediente, 'partidos': partidos, 'departamentosInternos':departamentosInternos, 'departamentosExternos':departamentosExternos, 'tipo':tipo, 'accion':'editar', 'pases':pases, 'organismoFiltro' : organismo, 'numeroFiltro': numero, 'fecha_inicioFiltro' :fecha_inicio, 'departamento_origen' : departamento_origen, 'proximo_pase_id': str( proximo_pase_id ) }, context_instance=RequestContext(request))
  File "/home/mmanto/virtualenvs3/python3.4/lib/python3.4/site-packages/django/shortcuts.py", line 50, in render
    return HttpResponse(loader.render_to_string(*args, **kwargs),
  File "/home/mmanto/virtualenvs3/python3.4/lib/python3.4/site-packages/django/template/loader.py", line 170, in render_to_string
    t = get_template(template_name, dirs)
  File "/home/mmanto/virtualenvs3/python3.4/lib/python3.4/site-packages/django/template/loader.py", line 144, in get_template
    template, origin = find_template(template_name, dirs)
  File "/home/mmanto/virtualenvs3/python3.4/lib/python3.4/site-packages/django/template/loader.py", line 132, in find_template
    source, display_name = loader(name, dirs)
  File "/home/mmanto/virtualenvs3/python3.4/lib/python3.4/site-packages/django/template/loader.py", line 44, in __call__
    return self.load_template(template_name, template_dirs)
  File "/home/mmanto/virtualenvs3/python3.4/lib/python3.4/site-packages/django/template/loader.py", line 50, in load_template
    template = get_template_from_string(source, origin, template_name)
  File "/home/mmanto/virtualenvs3/python3.4/lib/python3.4/site-packages/django/template/loader.py", line 156, in get_template_from_string
    return Template(source, origin, name)
  File "/home/mmanto/virtualenvs3/python3.4/lib/python3.4/site-packages/django/template/base.py", line 132, in __init__
    self.nodelist = compile_string(template_string, origin)
  File "/home/mmanto/virtualenvs3/python3.4/lib/python3.4/site-packages/django/template/base.py", line 162, in compile_string
    return parser.parse()
  File "/home/mmanto/virtualenvs3/python3.4/lib/python3.4/site-packages/django/template/base.py", line 290, in parse
    compiled_result = compile_func(self, token)
  File "/home/mmanto/virtualenvs3/python3.4/lib/python3.4/site-packages/django/template/loader_tags.py", line 201, in do_extends
    nodelist = parser.parse()
  File "/home/mmanto/virtualenvs3/python3.4/lib/python3.4/site-packages/django/template/base.py", line 290, in parse
    compiled_result = compile_func(self, token)
  File "/home/mmanto/virtualenvs3/python3.4/lib/python3.4/site-packages/django/template/loader_tags.py", line 175, in do_block
    nodelist = parser.parse(('endblock',))
  File "/home/mmanto/virtualenvs3/python3.4/lib/python3.4/site-packages/django/template/base.py", line 290, in parse
    compiled_result = compile_func(self, token)
  File "/home/mmanto/virtualenvs3/python3.4/lib/python3.4/site-packages/django/template/defaulttags.py", line 975, in do_if
    nodelist = parser.parse(('elif', 'else', 'endif'))
  File "/home/mmanto/virtualenvs3/python3.4/lib/python3.4/site-packages/django/template/base.py", line 266, in parse
    filter_expression = self.compile_filter(token.contents)
  File "/home/mmanto/virtualenvs3/python3.4/lib/python3.4/site-packages/django/template/base.py", line 372, in compile_filter
    return FilterExpression(token, self)
  File "/home/mmanto/virtualenvs3/python3.4/lib/python3.4/site-packages/django/template/base.py", line 588, in __init__
    "from '%s'" % (token[upto:], token))
django.template.base.TemplateSyntaxError: Could not parse the remainder: ' + '2015'' from 'proximo_pase_id + '2015''
[06/May/2015 15:44:47] ERROR [django.request:231] Internal Server Error: /sig/expediente/inspeccionar/Expediente/2423/33333333/2025/0/0/0/
Traceback (most recent call last):
  File "/home/mmanto/virtualenvs3/python3.4/lib/python3.4/site-packages/django/core/handlers/base.py", line 111, in get_response
    response = wrapped_callback(request, *callback_args, **callback_kwargs)
  File "/home/mmanto/virtualenvs3/python3.4/lib/python3.4/site-packages/django/contrib/auth/decorators.py", line 21, in _wrapped_view
    return view_func(request, *args, **kwargs)
  File "/home/mmanto/git/sstuv/documentos/views.py", line 77, in showExpediente
    return render(request, 'expediente_ley.html', {'expediente': expediente, 'partidos': partidos, 'departamentosInternos':departamentosInternos, 'departamentosExternos':departamentosExternos, 'tipo':tipo, 'accion':'editar', 'pases':pases, 'organismoFiltro' : organismo, 'numeroFiltro': numero, 'fecha_inicioFiltro' :fecha_inicio, 'departamento_origen' : departamento_origen, 'proximo_pase_id': str( proximo_pase_id ) }, context_instance=RequestContext(request))
  File "/home/mmanto/virtualenvs3/python3.4/lib/python3.4/site-packages/django/shortcuts.py", line 50, in render
    return HttpResponse(loader.render_to_string(*args, **kwargs),
  File "/home/mmanto/virtualenvs3/python3.4/lib/python3.4/site-packages/django/template/loader.py", line 170, in render_to_string
    t = get_template(template_name, dirs)
  File "/home/mmanto/virtualenvs3/python3.4/lib/python3.4/site-packages/django/template/loader.py", line 144, in get_template
    template, origin = find_template(template_name, dirs)
  File "/home/mmanto/virtualenvs3/python3.4/lib/python3.4/site-packages/django/template/loader.py", line 132, in find_template
    source, display_name = loader(name, dirs)
  File "/home/mmanto/virtualenvs3/python3.4/lib/python3.4/site-packages/django/template/loader.py", line 44, in __call__
    return self.load_template(template_name, template_dirs)
  File "/home/mmanto/virtualenvs3/python3.4/lib/python3.4/site-packages/django/template/loader.py", line 50, in load_template
    template = get_template_from_string(source, origin, template_name)
  File "/home/mmanto/virtualenvs3/python3.4/lib/python3.4/site-packages/django/template/loader.py", line 156, in get_template_from_string
    return Template(source, origin, name)
  File "/home/mmanto/virtualenvs3/python3.4/lib/python3.4/site-packages/django/template/base.py", line 132, in __init__
    self.nodelist = compile_string(template_string, origin)
  File "/home/mmanto/virtualenvs3/python3.4/lib/python3.4/site-packages/django/template/base.py", line 162, in compile_string
    return parser.parse()
  File "/home/mmanto/virtualenvs3/python3.4/lib/python3.4/site-packages/django/template/base.py", line 290, in parse
    compiled_result = compile_func(self, token)
  File "/home/mmanto/virtualenvs3/python3.4/lib/python3.4/site-packages/django/template/loader_tags.py", line 201, in do_extends
    nodelist = parser.parse()
  File "/home/mmanto/virtualenvs3/python3.4/lib/python3.4/site-packages/django/template/base.py", line 290, in parse
    compiled_result = compile_func(self, token)
  File "/home/mmanto/virtualenvs3/python3.4/lib/python3.4/site-packages/django/template/loader_tags.py", line 175, in do_block
    nodelist = parser.parse(('endblock',))
  File "/home/mmanto/virtualenvs3/python3.4/lib/python3.4/site-packages/django/template/base.py", line 290, in parse
    compiled_result = compile_func(self, token)
  File "/home/mmanto/virtualenvs3/python3.4/lib/python3.4/site-packages/django/template/defaulttags.py", line 975, in do_if
    nodelist = parser.parse(('elif', 'else', 'endif'))
  File "/home/mmanto/virtualenvs3/python3.4/lib/python3.4/site-packages/django/template/base.py", line 266, in parse
    filter_expression = self.compile_filter(token.contents)
  File "/home/mmanto/virtualenvs3/python3.4/lib/python3.4/site-packages/django/template/base.py", line 372, in compile_filter
    return FilterExpression(token, self)
  File "/home/mmanto/virtualenvs3/python3.4/lib/python3.4/site-packages/django/template/base.py", line 588, in __init__
    "from '%s'" % (token[upto:], token))
django.template.base.TemplateSyntaxError: Could not parse the remainder: ' + 2015' from 'proximo_pase_id + 2015'
[06/May/2015 18:10:37] ERROR [django.request:231] Internal Server Error: /sig/expediente/inspeccionar/Expediente/2423/33333333/2025/0/0/0/
Traceback (most recent call last):
  File "/home/mmanto/virtualenvs3/python3.4/lib/python3.4/site-packages/django/core/handlers/base.py", line 111, in get_response
    response = wrapped_callback(request, *callback_args, **callback_kwargs)
  File "/home/mmanto/virtualenvs3/python3.4/lib/python3.4/site-packages/django/contrib/auth/decorators.py", line 21, in _wrapped_view
    return view_func(request, *args, **kwargs)
  File "/home/mmanto/git/sstuv/documentos/views.py", line 76, in showExpediente
    proximo_pase_id = str(proximo_pase_id) + str(datetime.date.today().year)
AttributeError: 'method_descriptor' object has no attribute 'today'
[06/May/2015 18:12:03] ERROR [django.request:231] Internal Server Error: /sig/pase/guardar/
Traceback (most recent call last):
  File "/home/mmanto/virtualenvs3/python3.4/lib/python3.4/site-packages/django/core/handlers/base.py", line 111, in get_response
    response = wrapped_callback(request, *callback_args, **callback_kwargs)
  File "/home/mmanto/virtualenvs3/python3.4/lib/python3.4/site-packages/django/contrib/auth/decorators.py", line 21, in _wrapped_view
    return view_func(request, *args, **kwargs)
  File "/home/mmanto/git/sstuv/documentos/views.py", line 365, in savePase
    pase.departamento_destino = Departamento.objects.get(codigo=int (request.POST.get('departamento_destino')))
ValueError: invalid literal for int() with base 10: ''
[06/May/2015 18:15:15] INFO [sstuvInfo:90] busqueda de expedientes en logger info
[07/May/2015 12:13:32] INFO [sstuvInfo:90] busqueda de expedientes en logger info
[07/May/2015 12:24:52] INFO [sstuvInfo:90] busqueda de expedientes en logger info
[07/May/2015 13:50:27] ERROR [django.request:231] Internal Server Error: /sig/expedientes/guardar/
Traceback (most recent call last):
  File "/home/mmanto/virtualenvs3/python3.4/lib/python3.4/site-packages/django/core/urlresolvers.py", line 364, in urlconf_module
    return self._urlconf_module
AttributeError: 'RegexURLResolver' object has no attribute '_urlconf_module'

During handling of the above exception, another exception occurred:

Traceback (most recent call last):
  File "/home/mmanto/virtualenvs3/python3.4/lib/python3.4/site-packages/django/core/handlers/base.py", line 98, in get_response
    resolver_match = resolver.resolve(request.path_info)
  File "/home/mmanto/virtualenvs3/python3.4/lib/python3.4/site-packages/django/core/urlresolvers.py", line 343, in resolve
    for pattern in self.url_patterns:
  File "/home/mmanto/virtualenvs3/python3.4/lib/python3.4/site-packages/django/core/urlresolvers.py", line 372, in url_patterns
    patterns = getattr(self.urlconf_module, "urlpatterns", self.urlconf_module)
  File "/home/mmanto/virtualenvs3/python3.4/lib/python3.4/site-packages/django/core/urlresolvers.py", line 366, in urlconf_module
    self._urlconf_module = import_module(self.urlconf_name)
  File "/home/mmanto/virtualenvs3/python3.4/lib/python3.4/importlib/__init__.py", line 109, in import_module
    return _bootstrap._gcd_import(name[level:], package, level)
  File "<frozen importlib._bootstrap>", line 2254, in _gcd_import
  File "<frozen importlib._bootstrap>", line 2237, in _find_and_load
  File "<frozen importlib._bootstrap>", line 2226, in _find_and_load_unlocked
  File "<frozen importlib._bootstrap>", line 1200, in _load_unlocked
  File "<frozen importlib._bootstrap>", line 1129, in _exec
  File "<frozen importlib._bootstrap>", line 1471, in exec_module
  File "<frozen importlib._bootstrap>", line 321, in _call_with_frames_removed
  File "/home/mmanto/git/sstuv/sstuv/urls.py", line 7, in <module>
    from documentos import documentos_sites
  File "/home/mmanto/git/sstuv/documentos/documentos_sites.py", line 3, in <module>
    from documentos.views import ExpedientesView, PasesView
  File "/home/mmanto/git/sstuv/documentos/views.py", line 20, in <module>
    from date import date
ImportError: No module named 'date'
[07/May/2015 13:52:02] ERROR [django.request:231] Internal Server Error: /sig/expedientes/guardar/
Traceback (most recent call last):
  File "/home/mmanto/virtualenvs3/python3.4/lib/python3.4/site-packages/django/core/urlresolvers.py", line 364, in urlconf_module
    return self._urlconf_module
AttributeError: 'RegexURLResolver' object has no attribute '_urlconf_module'

During handling of the above exception, another exception occurred:

Traceback (most recent call last):
  File "/home/mmanto/virtualenvs3/python3.4/lib/python3.4/site-packages/django/core/handlers/base.py", line 98, in get_response
    resolver_match = resolver.resolve(request.path_info)
  File "/home/mmanto/virtualenvs3/python3.4/lib/python3.4/site-packages/django/core/urlresolvers.py", line 343, in resolve
    for pattern in self.url_patterns:
  File "/home/mmanto/virtualenvs3/python3.4/lib/python3.4/site-packages/django/core/urlresolvers.py", line 372, in url_patterns
    patterns = getattr(self.urlconf_module, "urlpatterns", self.urlconf_module)
  File "/home/mmanto/virtualenvs3/python3.4/lib/python3.4/site-packages/django/core/urlresolvers.py", line 366, in urlconf_module
    self._urlconf_module = import_module(self.urlconf_name)
  File "/home/mmanto/virtualenvs3/python3.4/lib/python3.4/importlib/__init__.py", line 109, in import_module
    return _bootstrap._gcd_import(name[level:], package, level)
  File "<frozen importlib._bootstrap>", line 2254, in _gcd_import
  File "<frozen importlib._bootstrap>", line 2237, in _find_and_load
  File "<frozen importlib._bootstrap>", line 2226, in _find_and_load_unlocked
  File "<frozen importlib._bootstrap>", line 1200, in _load_unlocked
  File "<frozen importlib._bootstrap>", line 1129, in _exec
  File "<frozen importlib._bootstrap>", line 1471, in exec_module
  File "<frozen importlib._bootstrap>", line 321, in _call_with_frames_removed
  File "/home/mmanto/git/sstuv/sstuv/urls.py", line 7, in <module>
    from documentos import documentos_sites
  File "/home/mmanto/git/sstuv/documentos/documentos_sites.py", line 3, in <module>
    from documentos.views import ExpedientesView, PasesView
  File "/home/mmanto/git/sstuv/documentos/views.py", line 20, in <module>
    from date import date
ImportError: No module named 'date'
[07/May/2015 13:55:09] INFO [sstuvInfo:90] busqueda de expedientes en logger info
[07/May/2015 13:55:37] INFO [sstuvInfo:90] busqueda de expedientes en logger info
[07/May/2015 13:56:48] INFO [sstuvInfo:90] busqueda de expedientes en logger info
[07/May/2015 13:57:47] ERROR [django.request:231] Internal Server Error: /sig/expedientes/guardar/
Traceback (most recent call last):
  File "/home/mmanto/virtualenvs3/python3.4/lib/python3.4/site-packages/django/core/handlers/base.py", line 111, in get_response
    response = wrapped_callback(request, *callback_args, **callback_kwargs)
  File "/home/mmanto/virtualenvs3/python3.4/lib/python3.4/site-packages/django/contrib/auth/decorators.py", line 21, in _wrapped_view
    return view_func(request, *args, **kwargs)
  File "/home/mmanto/git/sstuv/documentos/views.py", line 175, in saveExpediente
    guardar_pase( origen_destino, origen_destino, exp )
NameError: name 'guardar_pase' is not defined
[07/May/2015 13:59:24] ERROR [django.request:231] Internal Server Error: /sig/expedientes/guardar/
Traceback (most recent call last):
  File "/home/mmanto/virtualenvs3/python3.4/lib/python3.4/site-packages/django/core/handlers/base.py", line 111, in get_response
    response = wrapped_callback(request, *callback_args, **callback_kwargs)
  File "/home/mmanto/virtualenvs3/python3.4/lib/python3.4/site-packages/django/contrib/auth/decorators.py", line 21, in _wrapped_view
    return view_func(request, *args, **kwargs)
  File "/home/mmanto/git/sstuv/documentos/views.py", line 209, in saveExpediente
    expediente.fecha = datetime.strptime(request.POST.get('fecha'), "%d/%m/%Y")  # datetime.strptime( fecha, "%M/%d/%Y" )
  File "/usr/lib/python3.4/_strptime.py", line 500, in _strptime_datetime
    tt, fraction = _strptime(data_string, format)
  File "/usr/lib/python3.4/_strptime.py", line 337, in _strptime
    (data_string, format))
ValueError: time data '1 Mayo 2025' does not match format '%d/%m/%Y'
[07/May/2015 14:03:12] ERROR [django.request:231] Internal Server Error: /sig/expedientes/guardar/
Traceback (most recent call last):
  File "/home/mmanto/virtualenvs3/python3.4/lib/python3.4/site-packages/django/core/handlers/base.py", line 111, in get_response
    response = wrapped_callback(request, *callback_args, **callback_kwargs)
  File "/home/mmanto/virtualenvs3/python3.4/lib/python3.4/site-packages/django/contrib/auth/decorators.py", line 21, in _wrapped_view
    return view_func(request, *args, **kwargs)
  File "/home/mmanto/git/sstuv/documentos/views.py", line 209, in saveExpediente
    expediente.fecha = datetime.strptime(request.POST.get('fecha'), "%d/%m/%Y")  # datetime.strptime( fecha, "%M/%d/%Y" )
  File "/usr/lib/python3.4/_strptime.py", line 500, in _strptime_datetime
    tt, fraction = _strptime(data_string, format)
  File "/usr/lib/python3.4/_strptime.py", line 337, in _strptime
    (data_string, format))
ValueError: time data '1 Mayo 2025' does not match format '%d/%m/%Y'
[07/May/2015 14:13:01] ERROR [django.request:231] Internal Server Error: /sig/expedientes/guardar/
Traceback (most recent call last):
  File "/home/mmanto/virtualenvs3/python3.4/lib/python3.4/site-packages/django/core/handlers/base.py", line 111, in get_response
    response = wrapped_callback(request, *callback_args, **callback_kwargs)
  File "/home/mmanto/virtualenvs3/python3.4/lib/python3.4/site-packages/django/contrib/auth/decorators.py", line 21, in _wrapped_view
    return view_func(request, *args, **kwargs)
  File "/home/mmanto/git/sstuv/documentos/views.py", line 209, in saveExpediente
    expediente.fecha = datetime.strptime(request.POST.get('fecha'), "%d/%m/%Y")  # datetime.strptime( fecha, "%M/%d/%Y" )
TypeError: must be str, not None
[07/May/2015 14:13:39] ERROR [django.request:231] Internal Server Error: /sig/expedientes/guardar/
Traceback (most recent call last):
  File "/home/mmanto/virtualenvs3/python3.4/lib/python3.4/site-packages/django/core/handlers/base.py", line 111, in get_response
    response = wrapped_callback(request, *callback_args, **callback_kwargs)
  File "/home/mmanto/virtualenvs3/python3.4/lib/python3.4/site-packages/django/contrib/auth/decorators.py", line 21, in _wrapped_view
    return view_func(request, *args, **kwargs)
  File "/home/mmanto/git/sstuv/documentos/views.py", line 209, in saveExpediente
    expediente.fecha = datetime.strptime(request.POST.get('fecha_inicio'), "%d/%m/%Y")  # datetime.strptime( fecha, "%M/%d/%Y" )
TypeError: must be str, not None
[07/May/2015 14:13:53] ERROR [django.request:231] Internal Server Error: /sig/expedientes/guardar/
Traceback (most recent call last):
  File "/home/mmanto/virtualenvs3/python3.4/lib/python3.4/site-packages/django/core/handlers/base.py", line 111, in get_response
    response = wrapped_callback(request, *callback_args, **callback_kwargs)
  File "/home/mmanto/virtualenvs3/python3.4/lib/python3.4/site-packages/django/contrib/auth/decorators.py", line 21, in _wrapped_view
    return view_func(request, *args, **kwargs)
  File "/home/mmanto/git/sstuv/documentos/views.py", line 209, in saveExpediente
    expediente.fecha = datetime.strptime(request.POST.get('fecha_inicio'), "%d/%m/%Y")  # datetime.strptime( fecha, "%M/%d/%Y" )
TypeError: must be str, not None
[07/May/2015 14:13:58] ERROR [django.request:231] Internal Server Error: /sig/expedientes/guardar/
Traceback (most recent call last):
  File "/home/mmanto/virtualenvs3/python3.4/lib/python3.4/site-packages/django/core/handlers/base.py", line 111, in get_response
    response = wrapped_callback(request, *callback_args, **callback_kwargs)
  File "/home/mmanto/virtualenvs3/python3.4/lib/python3.4/site-packages/django/contrib/auth/decorators.py", line 21, in _wrapped_view
    return view_func(request, *args, **kwargs)
  File "/home/mmanto/git/sstuv/documentos/views.py", line 209, in saveExpediente
    expediente.fecha = datetime.strptime(request.POST.get('fecha_inicio'), "%d/%m/%Y")  # datetime.strptime( fecha, "%M/%d/%Y" )
TypeError: must be str, not None
[07/May/2015 14:20:02] INFO [sstuvInfo:90] busqueda de expedientes en logger info
[07/May/2015 14:20:05] INFO [sstuvInfo:90] busqueda de expedientes en logger info
[07/May/2015 14:20:40] ERROR [django.request:231] Internal Server Error: /sig/expedientes/guardar/
Traceback (most recent call last):
  File "/home/mmanto/virtualenvs3/python3.4/lib/python3.4/site-packages/django/core/handlers/base.py", line 111, in get_response
    response = wrapped_callback(request, *callback_args, **callback_kwargs)
  File "/home/mmanto/virtualenvs3/python3.4/lib/python3.4/site-packages/django/contrib/auth/decorators.py", line 21, in _wrapped_view
    return view_func(request, *args, **kwargs)
  File "/home/mmanto/git/sstuv/documentos/views.py", line 209, in saveExpediente
    expediente.fecha = datetime.strptime(request.POST.get('fecha_inicio'), "%d/%m/%Y")  # datetime.strptime( fecha, "%M/%d/%Y" )
  File "/usr/lib/python3.4/_strptime.py", line 500, in _strptime_datetime
    tt, fraction = _strptime(data_string, format)
  File "/usr/lib/python3.4/_strptime.py", line 337, in _strptime
    (data_string, format))
ValueError: time data '2025' does not match format '%d/%m/%Y'
[07/May/2015 14:22:53] ERROR [django.request:231] Internal Server Error: /sig/expedientes/guardar/
Traceback (most recent call last):
  File "/home/mmanto/virtualenvs3/python3.4/lib/python3.4/site-packages/django/core/handlers/base.py", line 111, in get_response
    response = wrapped_callback(request, *callback_args, **callback_kwargs)
  File "/home/mmanto/virtualenvs3/python3.4/lib/python3.4/site-packages/django/contrib/auth/decorators.py", line 21, in _wrapped_view
    return view_func(request, *args, **kwargs)
  File "/home/mmanto/git/sstuv/documentos/views.py", line 209, in saveExpediente
    expediente.fecha = datetime.strptime(request.POST.get('fecha_inicio'), "%d/%m/%Y")  # datetime.strptime( fecha, "%M/%d/%Y" )
  File "/usr/lib/python3.4/_strptime.py", line 500, in _strptime_datetime
    tt, fraction = _strptime(data_string, format)
  File "/usr/lib/python3.4/_strptime.py", line 337, in _strptime
    (data_string, format))
ValueError: time data '2025' does not match format '%d/%m/%Y'
[07/May/2015 14:24:35] ERROR [django.request:231] Internal Server Error: /sig/expedientes/guardar/
Traceback (most recent call last):
  File "/home/mmanto/virtualenvs3/python3.4/lib/python3.4/site-packages/django/core/handlers/base.py", line 111, in get_response
    response = wrapped_callback(request, *callback_args, **callback_kwargs)
  File "/home/mmanto/virtualenvs3/python3.4/lib/python3.4/site-packages/django/contrib/auth/decorators.py", line 21, in _wrapped_view
    return view_func(request, *args, **kwargs)
  File "/home/mmanto/git/sstuv/documentos/views.py", line 209, in saveExpediente
    expediente.fecha = datetime.strptime(request.POST.get('fecha_inicio'), "%d/%m/%Y")  # datetime.strptime( fecha, "%M/%d/%Y" )
  File "/usr/lib/python3.4/_strptime.py", line 500, in _strptime_datetime
    tt, fraction = _strptime(data_string, format)
  File "/usr/lib/python3.4/_strptime.py", line 337, in _strptime
    (data_string, format))
ValueError: time data '2025' does not match format '%d/%m/%Y'
[07/May/2015 14:25:07] ERROR [django.request:231] Internal Server Error: /sig/expedientes/guardar/
Traceback (most recent call last):
  File "/home/mmanto/virtualenvs3/python3.4/lib/python3.4/site-packages/django/core/handlers/base.py", line 111, in get_response
    response = wrapped_callback(request, *callback_args, **callback_kwargs)
  File "/home/mmanto/virtualenvs3/python3.4/lib/python3.4/site-packages/django/contrib/auth/decorators.py", line 21, in _wrapped_view
    return view_func(request, *args, **kwargs)
  File "/home/mmanto/git/sstuv/documentos/views.py", line 209, in saveExpediente
    expediente.fecha = datetime.strptime(request.POST.get('fecha_inicio'), "%d/%m/%Y")  # datetime.strptime( fecha, "%M/%d/%Y" )
  File "/usr/lib/python3.4/_strptime.py", line 500, in _strptime_datetime
    tt, fraction = _strptime(data_string, format)
  File "/usr/lib/python3.4/_strptime.py", line 337, in _strptime
    (data_string, format))
ValueError: time data '2025' does not match format '%d/%m/%Y'
[07/May/2015 16:32:19] ERROR [django.request:231] Internal Server Error: /sig/expedientes/guardar/
Traceback (most recent call last):
  File "/home/mmanto/virtualenvs3/python3.4/lib/python3.4/site-packages/django/db/backends/utils.py", line 65, in execute
    return self.cursor.execute(sql, params)
psycopg2.ProgrammingError: no existe la columna documentos_expediente.fecha_inicio
LINE 1: ...ND "documentos_expediente"."organismo" = 2423 AND "documento...
                                                             ^


The above exception was the direct cause of the following exception:

Traceback (most recent call last):
  File "/home/mmanto/virtualenvs3/python3.4/lib/python3.4/site-packages/django/core/handlers/base.py", line 111, in get_response
    response = wrapped_callback(request, *callback_args, **callback_kwargs)
  File "/home/mmanto/virtualenvs3/python3.4/lib/python3.4/site-packages/django/contrib/auth/decorators.py", line 21, in _wrapped_view
    return view_func(request, *args, **kwargs)
  File "/home/mmanto/git/sstuv/documentos/views.py", line 167, in saveExpediente
    if(Expediente.objects.filter(organismo=request.POST.get('organismo') , numero=request.POST.get('numero'), fecha_inicio=request.POST.get('fecha_inicio')).exists()):
  File "/home/mmanto/virtualenvs3/python3.4/lib/python3.4/site-packages/django/db/models/query.py", line 606, in exists
    return self.query.has_results(using=self.db)
  File "/home/mmanto/virtualenvs3/python3.4/lib/python3.4/site-packages/django/db/models/sql/query.py", line 457, in has_results
    return compiler.has_results()
  File "/home/mmanto/virtualenvs3/python3.4/lib/python3.4/site-packages/django/db/models/sql/compiler.py", line 757, in has_results
    return bool(self.execute_sql(SINGLE))
  File "/home/mmanto/virtualenvs3/python3.4/lib/python3.4/site-packages/django/db/models/sql/compiler.py", line 786, in execute_sql
    cursor.execute(sql, params)
  File "/home/mmanto/virtualenvs3/python3.4/lib/python3.4/site-packages/django/db/backends/utils.py", line 81, in execute
    return super(CursorDebugWrapper, self).execute(sql, params)
  File "/home/mmanto/virtualenvs3/python3.4/lib/python3.4/site-packages/django/db/backends/utils.py", line 65, in execute
    return self.cursor.execute(sql, params)
  File "/home/mmanto/virtualenvs3/python3.4/lib/python3.4/site-packages/django/db/utils.py", line 94, in __exit__
    six.reraise(dj_exc_type, dj_exc_value, traceback)
  File "/home/mmanto/virtualenvs3/python3.4/lib/python3.4/site-packages/django/utils/six.py", line 658, in reraise
    raise value.with_traceback(tb)
  File "/home/mmanto/virtualenvs3/python3.4/lib/python3.4/site-packages/django/db/backends/utils.py", line 65, in execute
    return self.cursor.execute(sql, params)
django.db.utils.ProgrammingError: no existe la columna documentos_expediente.fecha_inicio
LINE 1: ...ND "documentos_expediente"."organismo" = 2423 AND "documento...
                                                             ^

[07/May/2015 16:34:33] ERROR [django.request:231] Internal Server Error: /sig/expedientes/guardar/
Traceback (most recent call last):
  File "/home/mmanto/virtualenvs3/python3.4/lib/python3.4/site-packages/django/core/handlers/base.py", line 111, in get_response
    response = wrapped_callback(request, *callback_args, **callback_kwargs)
  File "/home/mmanto/virtualenvs3/python3.4/lib/python3.4/site-packages/django/contrib/auth/decorators.py", line 21, in _wrapped_view
    return view_func(request, *args, **kwargs)
  File "/home/mmanto/git/sstuv/documentos/views.py", line 175, in saveExpediente
    guardar_pase( depto_mesa_entrada, depto_mesa_entrada, exp )
NameError: name 'guardar_pase' is not defined
[07/May/2015 16:36:19] ERROR [django.request:231] Internal Server Error: /sig/expedientes/guardar/
Traceback (most recent call last):
  File "/home/mmanto/virtualenvs3/python3.4/lib/python3.4/site-packages/django/core/handlers/base.py", line 111, in get_response
    response = wrapped_callback(request, *callback_args, **callback_kwargs)
  File "/home/mmanto/virtualenvs3/python3.4/lib/python3.4/site-packages/django/contrib/auth/decorators.py", line 21, in _wrapped_view
    return view_func(request, *args, **kwargs)
  File "/home/mmanto/git/sstuv/documentos/views.py", line 175, in saveExpediente
    guardar_pase( depto_mesa_entrada, depto_mesa_entrada, exp )
TypeError: guardar_pase() missing 1 required positional argument: 'expediente'
[07/May/2015 16:39:47] ERROR [django.request:231] Internal Server Error: /sig/expedientes/guardar/
Traceback (most recent call last):
  File "/home/mmanto/virtualenvs3/python3.4/lib/python3.4/site-packages/django/core/handlers/base.py", line 111, in get_response
    response = wrapped_callback(request, *callback_args, **callback_kwargs)
  File "/home/mmanto/virtualenvs3/python3.4/lib/python3.4/site-packages/django/contrib/auth/decorators.py", line 21, in _wrapped_view
    return view_func(request, *args, **kwargs)
  File "/home/mmanto/git/sstuv/documentos/views.py", line 175, in saveExpediente
    guardar_pase( depto_mesa_entrada, depto_mesa_entrada, exp )
  File "/home/mmanto/git/sstuv/documentos/views.py", line 428, in guardar_pase
    nuevo_pase.departamento_origen( origen )
  File "/home/mmanto/virtualenvs3/python3.4/lib/python3.4/site-packages/django/db/models/fields/related.py", line 578, in __get__
    "%s has no %s." % (self.field.model.__name__, self.field.name)
django.db.models.fields.related.RelatedObjectDoesNotExist: Pase has no departamento_origen.
[07/May/2015 16:42:07] ERROR [django.request:231] Internal Server Error: /sig/expedientes/guardar/
Traceback (most recent call last):
  File "/home/mmanto/virtualenvs3/python3.4/lib/python3.4/site-packages/django/core/handlers/base.py", line 111, in get_response
    response = wrapped_callback(request, *callback_args, **callback_kwargs)
  File "/home/mmanto/virtualenvs3/python3.4/lib/python3.4/site-packages/django/contrib/auth/decorators.py", line 21, in _wrapped_view
    return view_func(request, *args, **kwargs)
  File "/home/mmanto/git/sstuv/documentos/views.py", line 175, in saveExpediente
    guardar_pase( depto_mesa_entrada, depto_mesa_entrada )
TypeError: guardar_pase() missing 1 required positional argument: 'destino'
[07/May/2015 16:45:14] ERROR [django.request:231] Internal Server Error: /sig/expedientes/guardar/
Traceback (most recent call last):
  File "/home/mmanto/virtualenvs3/python3.4/lib/python3.4/site-packages/django/core/handlers/base.py", line 111, in get_response
    response = wrapped_callback(request, *callback_args, **callback_kwargs)
  File "/home/mmanto/virtualenvs3/python3.4/lib/python3.4/site-packages/django/contrib/auth/decorators.py", line 21, in _wrapped_view
    return view_func(request, *args, **kwargs)
  File "/home/mmanto/git/sstuv/documentos/views.py", line 176, in saveExpediente
    guardar_pase( depto_origen, depto_destino )
TypeError: guardar_pase() missing 1 required positional argument: 'destino'
[07/May/2015 16:45:51] ERROR [django.request:231] Internal Server Error: /sig/expedientes/guardar/
Traceback (most recent call last):
  File "/home/mmanto/virtualenvs3/python3.4/lib/python3.4/site-packages/django/core/handlers/base.py", line 111, in get_response
    response = wrapped_callback(request, *callback_args, **callback_kwargs)
  File "/home/mmanto/virtualenvs3/python3.4/lib/python3.4/site-packages/django/contrib/auth/decorators.py", line 21, in _wrapped_view
    return view_func(request, *args, **kwargs)
  File "/home/mmanto/git/sstuv/documentos/views.py", line 176, in saveExpediente
    guardar_pase( depto_origen, depto_destino )
TypeError: guardar_pase() missing 1 required positional argument: 'destino'
[07/May/2015 16:47:04] ERROR [django.request:231] Internal Server Error: /sig/expedientes/guardar/
Traceback (most recent call last):
  File "/home/mmanto/virtualenvs3/python3.4/lib/python3.4/site-packages/django/core/handlers/base.py", line 111, in get_response
    response = wrapped_callback(request, *callback_args, **callback_kwargs)
  File "/home/mmanto/virtualenvs3/python3.4/lib/python3.4/site-packages/django/contrib/auth/decorators.py", line 21, in _wrapped_view
    return view_func(request, *args, **kwargs)
  File "/home/mmanto/git/sstuv/documentos/views.py", line 176, in saveExpediente
    guardar_pase( depto_origen, depto_destino )
  File "/home/mmanto/git/sstuv/documentos/views.py", line 429, in guardar_pase
    nuevo_pase.departamento_origen( origen )
  File "/home/mmanto/virtualenvs3/python3.4/lib/python3.4/site-packages/django/db/models/fields/related.py", line 578, in __get__
    "%s has no %s." % (self.field.model.__name__, self.field.name)
django.db.models.fields.related.RelatedObjectDoesNotExist: Pase has no departamento_origen.
[07/May/2015 16:50:14] ERROR [django.request:231] Internal Server Error: /sig/expedientes/guardar/
Traceback (most recent call last):
  File "/home/mmanto/virtualenvs3/python3.4/lib/python3.4/site-packages/django/core/handlers/base.py", line 111, in get_response
    response = wrapped_callback(request, *callback_args, **callback_kwargs)
  File "/home/mmanto/virtualenvs3/python3.4/lib/python3.4/site-packages/django/contrib/auth/decorators.py", line 21, in _wrapped_view
    return view_func(request, *args, **kwargs)
  File "/home/mmanto/git/sstuv/documentos/views.py", line 176, in saveExpediente
    guardar_pase( depto_origen, depto_destino )
  File "/home/mmanto/git/sstuv/documentos/views.py", line 429, in guardar_pase
    nuevo_pase.departamento_origen( origen )
  File "/home/mmanto/virtualenvs3/python3.4/lib/python3.4/site-packages/django/db/models/fields/related.py", line 578, in __get__
    "%s has no %s." % (self.field.model.__name__, self.field.name)
django.db.models.fields.related.RelatedObjectDoesNotExist: Pase has no departamento_origen.
[07/May/2015 16:55:05] INFO [sstuvInfo:90] busqueda de expedientes en logger info
[07/May/2015 16:55:16] ERROR [django.request:231] Internal Server Error: /sig/expediente/inspeccionar/Expediente/2423/121222/2025/0/0/0/
Traceback (most recent call last):
  File "/home/mmanto/virtualenvs3/python3.4/lib/python3.4/site-packages/django/core/handlers/base.py", line 111, in get_response
    response = wrapped_callback(request, *callback_args, **callback_kwargs)
  File "/home/mmanto/virtualenvs3/python3.4/lib/python3.4/site-packages/django/contrib/auth/decorators.py", line 21, in _wrapped_view
    return view_func(request, *args, **kwargs)
  File "/home/mmanto/git/sstuv/documentos/views.py", line 73, in showExpediente
    pase_id_actual = expediente.pase_set.last().id
AttributeError: 'NoneType' object has no attribute 'id'
[07/May/2015 17:00:17] ERROR [django.request:231] Internal Server Error: /sig/expediente/inspeccionar/Expediente/2423/121222/2025/0/0/0/
Traceback (most recent call last):
  File "/home/mmanto/virtualenvs3/python3.4/lib/python3.4/site-packages/django/core/handlers/base.py", line 111, in get_response
    response = wrapped_callback(request, *callback_args, **callback_kwargs)
  File "/home/mmanto/virtualenvs3/python3.4/lib/python3.4/site-packages/django/contrib/auth/decorators.py", line 21, in _wrapped_view
    return view_func(request, *args, **kwargs)
  File "/home/mmanto/git/sstuv/documentos/views.py", line 79, in showExpediente
    pase_id_actual = pase_id_actual + 1
UnboundLocalError: local variable 'pase_id_actual' referenced before assignment
[07/May/2015 17:01:23] INFO [sstuvInfo:94] busqueda de expedientes en logger info
[07/May/2015 17:02:13] INFO [sstuvInfo:94] busqueda de expedientes en logger info
[07/May/2015 17:15:09] INFO [sstuvInfo:94] busqueda de expedientes en logger info
[07/May/2015 17:15:43] ERROR [django.request:231] Internal Server Error: /sig/expedientes/guardar/
Traceback (most recent call last):
  File "/home/mmanto/virtualenvs3/python3.4/lib/python3.4/site-packages/django/core/handlers/base.py", line 111, in get_response
    response = wrapped_callback(request, *callback_args, **callback_kwargs)
  File "/home/mmanto/virtualenvs3/python3.4/lib/python3.4/site-packages/django/contrib/auth/decorators.py", line 21, in _wrapped_view
    return view_func(request, *args, **kwargs)
  File "/home/mmanto/git/sstuv/documentos/views.py", line 180, in saveExpediente
    guardar_pase( depto_origen, depto_destino, expediente_instance )
  File "/home/mmanto/git/sstuv/documentos/views.py", line 436, in guardar_pase
    nuevo_pase.fecha( date.today.year )
AttributeError: 'builtin_function_or_method' object has no attribute 'year'
[07/May/2015 17:16:55] ERROR [django.request:231] Internal Server Error: /sig/expedientes/guardar/
Traceback (most recent call last):
  File "/home/mmanto/virtualenvs3/python3.4/lib/python3.4/site-packages/django/core/handlers/base.py", line 111, in get_response
    response = wrapped_callback(request, *callback_args, **callback_kwargs)
  File "/home/mmanto/virtualenvs3/python3.4/lib/python3.4/site-packages/django/contrib/auth/decorators.py", line 21, in _wrapped_view
    return view_func(request, *args, **kwargs)
  File "/home/mmanto/git/sstuv/documentos/views.py", line 180, in saveExpediente
    guardar_pase( depto_origen, depto_destino, expediente_instance )
  File "/home/mmanto/git/sstuv/documentos/views.py", line 436, in guardar_pase
    nuevo_pase.fecha( date.today().year )
TypeError: 'NoneType' object is not callable
[07/May/2015 17:20:34] INFO [sstuvInfo:94] busqueda de expedientes en logger info
[07/May/2015 17:20:49] INFO [sstuvInfo:94] busqueda de expedientes en logger info
[07/May/2015 17:31:21] ERROR [django.request:231] Internal Server Error: /sig/expedientes/guardar/
Traceback (most recent call last):
  File "/home/mmanto/virtualenvs3/python3.4/lib/python3.4/site-packages/django/core/handlers/base.py", line 111, in get_response
    response = wrapped_callback(request, *callback_args, **callback_kwargs)
  File "/home/mmanto/virtualenvs3/python3.4/lib/python3.4/site-packages/django/contrib/auth/decorators.py", line 21, in _wrapped_view
    return view_func(request, *args, **kwargs)
  File "/home/mmanto/git/sstuv/documentos/views.py", line 180, in saveExpediente
    guardar_pase( depto_origen, depto_destino, expediente_instance )
  File "/home/mmanto/git/sstuv/documentos/views.py", line 436, in guardar_pase
    nuevo_pase.fecha( date.today().year )
TypeError: 'NoneType' object is not callable
[07/May/2015 17:32:59] ERROR [django.request:231] Internal Server Error: /sig/expedientes/guardar/
Traceback (most recent call last):
  File "/home/mmanto/virtualenvs3/python3.4/lib/python3.4/site-packages/django/core/handlers/base.py", line 111, in get_response
    response = wrapped_callback(request, *callback_args, **callback_kwargs)
  File "/home/mmanto/virtualenvs3/python3.4/lib/python3.4/site-packages/django/contrib/auth/decorators.py", line 21, in _wrapped_view
    return view_func(request, *args, **kwargs)
  File "/home/mmanto/git/sstuv/documentos/views.py", line 180, in saveExpediente
    guardar_pase( depto_origen, depto_destino, expediente_instance )
  File "/home/mmanto/git/sstuv/documentos/views.py", line 436, in guardar_pase
    nuevo_pase.fecha( datetime.date.today().strftime("%Y") )
AttributeError: 'method_descriptor' object has no attribute 'today'
[07/May/2015 17:34:12] ERROR [django.request:231] Internal Server Error: /sig/expedientes/guardar/
Traceback (most recent call last):
  File "/home/mmanto/virtualenvs3/python3.4/lib/python3.4/site-packages/django/core/handlers/base.py", line 111, in get_response
    response = wrapped_callback(request, *callback_args, **callback_kwargs)
  File "/home/mmanto/virtualenvs3/python3.4/lib/python3.4/site-packages/django/contrib/auth/decorators.py", line 21, in _wrapped_view
    return view_func(request, *args, **kwargs)
  File "/home/mmanto/git/sstuv/documentos/views.py", line 180, in saveExpediente
    guardar_pase( depto_origen, depto_destino, expediente_instance )
  File "/home/mmanto/git/sstuv/documentos/views.py", line 436, in guardar_pase
    nuevo_pase.fecha( date.today().strftime("%Y") )
TypeError: 'NoneType' object is not callable
[07/May/2015 17:35:15] ERROR [django.request:231] Internal Server Error: /sig/expedientes/guardar/
Traceback (most recent call last):
  File "/home/mmanto/virtualenvs3/python3.4/lib/python3.4/site-packages/django/core/handlers/base.py", line 111, in get_response
    response = wrapped_callback(request, *callback_args, **callback_kwargs)
  File "/home/mmanto/virtualenvs3/python3.4/lib/python3.4/site-packages/django/contrib/auth/decorators.py", line 21, in _wrapped_view
    return view_func(request, *args, **kwargs)
  File "/home/mmanto/git/sstuv/documentos/views.py", line 215, in saveExpediente
    expediente.fecha_inicio = datetime.strptime(request.POST.get('fecha_inicio'), "%Y")  # datetime.strptime( fecha, "%M/%d/%Y" )
AttributeError: 'module' object has no attribute 'strptime'
[07/May/2015 17:37:58] ERROR [django.request:231] Internal Server Error: /sig/expedientes/guardar/
Traceback (most recent call last):
  File "/home/mmanto/virtualenvs3/python3.4/lib/python3.4/site-packages/django/core/handlers/base.py", line 111, in get_response
    response = wrapped_callback(request, *callback_args, **callback_kwargs)
  File "/home/mmanto/virtualenvs3/python3.4/lib/python3.4/site-packages/django/contrib/auth/decorators.py", line 21, in _wrapped_view
    return view_func(request, *args, **kwargs)
  File "/home/mmanto/git/sstuv/documentos/views.py", line 180, in saveExpediente
    guardar_pase( depto_origen, depto_destino, expediente_instance )
  File "/home/mmanto/git/sstuv/documentos/views.py", line 436, in guardar_pase
    nuevo_pase.fecha( datetime.datetime.now().year)
TypeError: 'NoneType' object is not callable
[07/May/2015 17:39:01] ERROR [django.request:231] Internal Server Error: /sig/expedientes/guardar/
Traceback (most recent call last):
  File "/home/mmanto/virtualenvs3/python3.4/lib/python3.4/site-packages/django/core/handlers/base.py", line 111, in get_response
    response = wrapped_callback(request, *callback_args, **callback_kwargs)
  File "/home/mmanto/virtualenvs3/python3.4/lib/python3.4/site-packages/django/contrib/auth/decorators.py", line 21, in _wrapped_view
    return view_func(request, *args, **kwargs)
  File "/home/mmanto/git/sstuv/documentos/views.py", line 215, in saveExpediente
    expediente.fecha_inicio = datetime.strptime(request.POST.get('fecha_inicio'), "%Y")  # datetime.strptime( fecha, "%M/%d/%Y" )
AttributeError: 'module' object has no attribute 'strptime'
[07/May/2015 17:44:56] ERROR [django.request:231] Internal Server Error: /sig/expediente/inspeccionar/Expediente/2423/121231/2025/0/0/0/
Traceback (most recent call last):
  File "/home/mmanto/virtualenvs3/python3.4/lib/python3.4/site-packages/django/core/handlers/base.py", line 111, in get_response
    response = wrapped_callback(request, *callback_args, **callback_kwargs)
  File "/home/mmanto/virtualenvs3/python3.4/lib/python3.4/site-packages/django/contrib/auth/decorators.py", line 21, in _wrapped_view
    return view_func(request, *args, **kwargs)
  File "/home/mmanto/git/sstuv/documentos/views.py", line 81, in showExpediente
    proximo_pase_id = str(proximo_pase_id) + str(date.today().year)
NameError: name 'date' is not defined
[07/May/2015 17:45:22] ERROR [django.request:231] Internal Server Error: /sig/expediente/inspeccionar/Expediente/2423/121222/2025/0/0/0/
Traceback (most recent call last):
  File "/home/mmanto/virtualenvs3/python3.4/lib/python3.4/site-packages/django/core/handlers/base.py", line 111, in get_response
    response = wrapped_callback(request, *callback_args, **callback_kwargs)
  File "/home/mmanto/virtualenvs3/python3.4/lib/python3.4/site-packages/django/contrib/auth/decorators.py", line 21, in _wrapped_view
    return view_func(request, *args, **kwargs)
  File "/home/mmanto/git/sstuv/documentos/views.py", line 81, in showExpediente
    proximo_pase_id = str(proximo_pase_id) + str(date.today().year)
NameError: name 'date' is not defined
[07/May/2015 17:45:44] INFO [sstuvInfo:94] busqueda de expedientes en logger info
[07/May/2015 17:46:13] ERROR [django.request:231] Internal Server Error: /sig/expedientes/guardar/
Traceback (most recent call last):
  File "/home/mmanto/virtualenvs3/python3.4/lib/python3.4/site-packages/django/core/handlers/base.py", line 111, in get_response
    response = wrapped_callback(request, *callback_args, **callback_kwargs)
  File "/home/mmanto/virtualenvs3/python3.4/lib/python3.4/site-packages/django/contrib/auth/decorators.py", line 21, in _wrapped_view
    return view_func(request, *args, **kwargs)
  File "/home/mmanto/git/sstuv/documentos/views.py", line 180, in saveExpediente
    guardar_pase( depto_origen, depto_destino, expediente_instance )
  File "/home/mmanto/git/sstuv/documentos/views.py", line 436, in guardar_pase
    now = datetime.datetime.now()
AttributeError: type object 'datetime.datetime' has no attribute 'datetime'
[07/May/2015 17:50:31] INFO [sstuvInfo:94] busqueda de expedientes en logger info
[07/May/2015 17:51:00] ERROR [django.request:231] Internal Server Error: /sig/expedientes/guardar/
Traceback (most recent call last):
  File "/home/mmanto/virtualenvs3/python3.4/lib/python3.4/site-packages/django/core/handlers/base.py", line 111, in get_response
    response = wrapped_callback(request, *callback_args, **callback_kwargs)
  File "/home/mmanto/virtualenvs3/python3.4/lib/python3.4/site-packages/django/contrib/auth/decorators.py", line 21, in _wrapped_view
    return view_func(request, *args, **kwargs)
  File "/home/mmanto/git/sstuv/documentos/views.py", line 180, in saveExpediente
    guardar_pase( depto_origen, depto_destino, expediente_instance )
  File "/home/mmanto/git/sstuv/documentos/views.py", line 437, in guardar_pase
    nuevo_pase.fecha( now.year)
TypeError: 'NoneType' object is not callable
[07/May/2015 17:56:04] ERROR [django.request:231] Internal Server Error: /sig/expedientes/guardar/
Traceback (most recent call last):
  File "/home/mmanto/virtualenvs3/python3.4/lib/python3.4/site-packages/django/core/handlers/base.py", line 111, in get_response
    response = wrapped_callback(request, *callback_args, **callback_kwargs)
  File "/home/mmanto/virtualenvs3/python3.4/lib/python3.4/site-packages/django/contrib/auth/decorators.py", line 21, in _wrapped_view
    return view_func(request, *args, **kwargs)
  File "/home/mmanto/git/sstuv/documentos/views.py", line 215, in saveExpediente
    expediente.fecha_inicio = datetime.strptime(request.POST.get('fecha_inicio'), "%Y")  # datetime.strptime( fecha, "%M/%d/%Y" )
AttributeError: 'module' object has no attribute 'strptime'
[07/May/2015 18:00:47] ERROR [django.request:231] Internal Server Error: /sig/expedientes/guardar/
Traceback (most recent call last):
  File "/home/mmanto/virtualenvs3/python3.4/lib/python3.4/site-packages/django/core/handlers/base.py", line 111, in get_response
    response = wrapped_callback(request, *callback_args, **callback_kwargs)
  File "/home/mmanto/virtualenvs3/python3.4/lib/python3.4/site-packages/django/contrib/auth/decorators.py", line 21, in _wrapped_view
    return view_func(request, *args, **kwargs)
  File "/home/mmanto/git/sstuv/documentos/views.py", line 215, in saveExpediente
    expediente.fecha_inicio = datetime.strptime(request.POST.get('fecha_inicio'), "%Y")  # datetime.strptime( fecha, "%M/%d/%Y" )
AttributeError: 'module' object has no attribute 'strptime'
[07/May/2015 18:01:45] ERROR [django.request:231] Internal Server Error: /sig/expedientes/guardar/
Traceback (most recent call last):
  File "/home/mmanto/virtualenvs3/python3.4/lib/python3.4/site-packages/django/core/handlers/base.py", line 111, in get_response
    response = wrapped_callback(request, *callback_args, **callback_kwargs)
  File "/home/mmanto/virtualenvs3/python3.4/lib/python3.4/site-packages/django/contrib/auth/decorators.py", line 21, in _wrapped_view
    return view_func(request, *args, **kwargs)
  File "/home/mmanto/git/sstuv/documentos/views.py", line 180, in saveExpediente
    guardar_pase( depto_origen, depto_destino, expediente_instance )
  File "/home/mmanto/git/sstuv/documentos/views.py", line 436, in guardar_pase
    now = datetime.now()
AttributeError: 'module' object has no attribute 'now'
[07/May/2015 18:02:16] ERROR [django.request:231] Internal Server Error: /sig/expedientes/guardar/
Traceback (most recent call last):
  File "/home/mmanto/virtualenvs3/python3.4/lib/python3.4/site-packages/django/core/handlers/base.py", line 111, in get_response
    response = wrapped_callback(request, *callback_args, **callback_kwargs)
  File "/home/mmanto/virtualenvs3/python3.4/lib/python3.4/site-packages/django/contrib/auth/decorators.py", line 21, in _wrapped_view
    return view_func(request, *args, **kwargs)
  File "/home/mmanto/git/sstuv/documentos/views.py", line 180, in saveExpediente
    guardar_pase( depto_origen, depto_destino, expediente_instance )
  File "/home/mmanto/git/sstuv/documentos/views.py", line 436, in guardar_pase
    now = adtetime.datetime.now()
NameError: name 'adtetime' is not defined
[07/May/2015 18:03:15] ERROR [django.request:231] Internal Server Error: /sig/expediente/inspeccionar/Expediente/2423/4999999999/2025/0/0/0/
Traceback (most recent call last):
  File "/home/mmanto/virtualenvs3/python3.4/lib/python3.4/site-packages/django/core/handlers/base.py", line 111, in get_response
    response = wrapped_callback(request, *callback_args, **callback_kwargs)
  File "/home/mmanto/virtualenvs3/python3.4/lib/python3.4/site-packages/django/contrib/auth/decorators.py", line 21, in _wrapped_view
    return view_func(request, *args, **kwargs)
  File "/home/mmanto/git/sstuv/documentos/views.py", line 81, in showExpediente
    proximo_pase_id = str(proximo_pase_id) + str(date.today().year)
NameError: name 'date' is not defined
[07/May/2015 18:03:47] INFO [sstuvInfo:94] busqueda de expedientes en logger info
[07/May/2015 18:04:15] ERROR [django.request:231] Internal Server Error: /sig/expedientes/guardar/
Traceback (most recent call last):
  File "/home/mmanto/virtualenvs3/python3.4/lib/python3.4/site-packages/django/core/handlers/base.py", line 111, in get_response
    response = wrapped_callback(request, *callback_args, **callback_kwargs)
  File "/home/mmanto/virtualenvs3/python3.4/lib/python3.4/site-packages/django/contrib/auth/decorators.py", line 21, in _wrapped_view
    return view_func(request, *args, **kwargs)
  File "/home/mmanto/git/sstuv/documentos/views.py", line 180, in saveExpediente
    guardar_pase( depto_origen, depto_destino, expediente_instance )
  File "/home/mmanto/git/sstuv/documentos/views.py", line 437, in guardar_pase
    nuevo_pase.fecha( now.year)
TypeError: 'NoneType' object is not callable
[07/May/2015 18:05:16] ERROR [django.request:231] Internal Server Error: /sig/expedientes/guardar/
Traceback (most recent call last):
  File "/home/mmanto/virtualenvs3/python3.4/lib/python3.4/site-packages/django/core/handlers/base.py", line 111, in get_response
    response = wrapped_callback(request, *callback_args, **callback_kwargs)
  File "/home/mmanto/virtualenvs3/python3.4/lib/python3.4/site-packages/django/contrib/auth/decorators.py", line 21, in _wrapped_view
    return view_func(request, *args, **kwargs)
  File "/home/mmanto/git/sstuv/documentos/views.py", line 180, in saveExpediente
    guardar_pase( depto_origen, depto_destino, expediente_instance )
  File "/home/mmanto/git/sstuv/documentos/views.py", line 436, in guardar_pase
    now = datetime.date.now()
AttributeError: type object 'datetime.date' has no attribute 'now'
[07/May/2015 18:05:40] ERROR [django.request:231] Internal Server Error: /sig/expedientes/guardar/
Traceback (most recent call last):
  File "/home/mmanto/virtualenvs3/python3.4/lib/python3.4/site-packages/django/core/handlers/base.py", line 111, in get_response
    response = wrapped_callback(request, *callback_args, **callback_kwargs)
  File "/home/mmanto/virtualenvs3/python3.4/lib/python3.4/site-packages/django/contrib/auth/decorators.py", line 21, in _wrapped_view
    return view_func(request, *args, **kwargs)
  File "/home/mmanto/git/sstuv/documentos/views.py", line 180, in saveExpediente
    guardar_pase( depto_origen, depto_destino, expediente_instance )
  File "/home/mmanto/git/sstuv/documentos/views.py", line 437, in guardar_pase
    nuevo_pase.fecha( now.year)
TypeError: 'NoneType' object is not callable
[07/May/2015 18:07:01] ERROR [django.request:231] Internal Server Error: /sig/expedientes/guardar/
Traceback (most recent call last):
  File "/home/mmanto/virtualenvs3/python3.4/lib/python3.4/site-packages/django/core/handlers/base.py", line 111, in get_response
    response = wrapped_callback(request, *callback_args, **callback_kwargs)
  File "/home/mmanto/virtualenvs3/python3.4/lib/python3.4/site-packages/django/contrib/auth/decorators.py", line 21, in _wrapped_view
    return view_func(request, *args, **kwargs)
  File "/home/mmanto/git/sstuv/documentos/views.py", line 180, in saveExpediente
    guardar_pase( depto_origen, depto_destino, expediente_instance )
  File "/home/mmanto/git/sstuv/documentos/views.py", line 437, in guardar_pase
    nuevo_pase.fecha( now.year)
AttributeError: 'builtin_function_or_method' object has no attribute 'year'
[07/May/2015 18:08:40] INFO [sstuvInfo:94] busqueda de expedientes en logger info
[07/May/2015 18:09:07] ERROR [django.request:231] Internal Server Error: /sig/expedientes/guardar/
Traceback (most recent call last):
  File "/home/mmanto/virtualenvs3/python3.4/lib/python3.4/site-packages/django/core/handlers/base.py", line 111, in get_response
    response = wrapped_callback(request, *callback_args, **callback_kwargs)
  File "/home/mmanto/virtualenvs3/python3.4/lib/python3.4/site-packages/django/contrib/auth/decorators.py", line 21, in _wrapped_view
    return view_func(request, *args, **kwargs)
  File "/home/mmanto/git/sstuv/documentos/views.py", line 180, in saveExpediente
    guardar_pase( depto_origen, depto_destino, expediente_instance )
  File "/home/mmanto/git/sstuv/documentos/views.py", line 438, in guardar_pase
    nuevo_pase.fecha( now.year)
TypeError: 'NoneType' object is not callable
[07/May/2015 18:10:04] ERROR [django.request:231] Internal Server Error: /sig/expedientes/guardar/
Traceback (most recent call last):
  File "/home/mmanto/virtualenvs3/python3.4/lib/python3.4/site-packages/django/core/handlers/base.py", line 111, in get_response
    response = wrapped_callback(request, *callback_args, **callback_kwargs)
  File "/home/mmanto/virtualenvs3/python3.4/lib/python3.4/site-packages/django/contrib/auth/decorators.py", line 21, in _wrapped_view
    return view_func(request, *args, **kwargs)
  File "/home/mmanto/git/sstuv/documentos/views.py", line 180, in saveExpediente
    guardar_pase( depto_origen, depto_destino, expediente_instance )
  File "/home/mmanto/git/sstuv/documentos/views.py", line 437, in guardar_pase
    print('now' + now)
TypeError: Can't convert 'datetime.date' object to str implicitly
[07/May/2015 18:13:06] ERROR [django.request:231] Internal Server Error: /sig/expedientes/guardar/
Traceback (most recent call last):
  File "/home/mmanto/virtualenvs3/python3.4/lib/python3.4/site-packages/django/core/handlers/base.py", line 111, in get_response
    response = wrapped_callback(request, *callback_args, **callback_kwargs)
  File "/home/mmanto/virtualenvs3/python3.4/lib/python3.4/site-packages/django/contrib/auth/decorators.py", line 21, in _wrapped_view
    return view_func(request, *args, **kwargs)
  File "/home/mmanto/git/sstuv/documentos/views.py", line 180, in saveExpediente
    guardar_pase( depto_origen, depto_destino, expediente_instance )
  File "/home/mmanto/git/sstuv/documentos/views.py", line 437, in guardar_pase
    print('now' + now)
TypeError: Can't convert 'datetime.datetime' object to str implicitly
[07/May/2015 18:14:07] ERROR [django.request:231] Internal Server Error: /sig/expedientes/guardar/
Traceback (most recent call last):
  File "/home/mmanto/virtualenvs3/python3.4/lib/python3.4/site-packages/django/core/handlers/base.py", line 111, in get_response
    response = wrapped_callback(request, *callback_args, **callback_kwargs)
  File "/home/mmanto/virtualenvs3/python3.4/lib/python3.4/site-packages/django/contrib/auth/decorators.py", line 21, in _wrapped_view
    return view_func(request, *args, **kwargs)
  File "/home/mmanto/git/sstuv/documentos/views.py", line 180, in saveExpediente
    guardar_pase( depto_origen, depto_destino, expediente_instance )
  File "/home/mmanto/git/sstuv/documentos/views.py", line 437, in guardar_pase
    print('now' + now.year)
TypeError: Can't convert 'int' object to str implicitly
[07/May/2015 18:14:37] ERROR [django.request:231] Internal Server Error: /sig/expedientes/guardar/
Traceback (most recent call last):
  File "/home/mmanto/virtualenvs3/python3.4/lib/python3.4/site-packages/django/core/handlers/base.py", line 111, in get_response
    response = wrapped_callback(request, *callback_args, **callback_kwargs)
  File "/home/mmanto/virtualenvs3/python3.4/lib/python3.4/site-packages/django/contrib/auth/decorators.py", line 21, in _wrapped_view
    return view_func(request, *args, **kwargs)
  File "/home/mmanto/git/sstuv/documentos/views.py", line 180, in saveExpediente
    guardar_pase( depto_origen, depto_destino, expediente_instance )
  File "/home/mmanto/git/sstuv/documentos/views.py", line 438, in guardar_pase
    nuevo_pase.fecha( now.year)
TypeError: 'NoneType' object is not callable
[07/May/2015 18:15:37] ERROR [django.request:231] Internal Server Error: /sig/expedientes/guardar/
Traceback (most recent call last):
  File "/home/mmanto/virtualenvs3/python3.4/lib/python3.4/site-packages/django/core/handlers/base.py", line 111, in get_response
    response = wrapped_callback(request, *callback_args, **callback_kwargs)
  File "/home/mmanto/virtualenvs3/python3.4/lib/python3.4/site-packages/django/contrib/auth/decorators.py", line 21, in _wrapped_view
    return view_func(request, *args, **kwargs)
  File "/home/mmanto/git/sstuv/documentos/views.py", line 180, in saveExpediente
    guardar_pase( depto_origen, depto_destino, expediente_instance )
  File "/home/mmanto/git/sstuv/documentos/views.py", line 440, in guardar_pase
    nuevo_pase.expediente = expediente
  File "/home/mmanto/virtualenvs3/python3.4/lib/python3.4/site-packages/django/db/models/fields/related.py", line 589, in __set__
    (instance._meta.object_name, self.field.name)
ValueError: Cannot assign None: "Pase.expediente" does not allow null values.
[08/May/2015 12:45:04] ERROR [django.request:231] Internal Server Error: /sig/expedientes/guardar/
Traceback (most recent call last):
  File "/home/mmanto/virtualenvs3/python3.4/lib/python3.4/site-packages/django/core/handlers/base.py", line 111, in get_response
    response = wrapped_callback(request, *callback_args, **callback_kwargs)
  File "/home/mmanto/virtualenvs3/python3.4/lib/python3.4/site-packages/django/contrib/auth/decorators.py", line 21, in _wrapped_view
    return view_func(request, *args, **kwargs)
  File "/home/mmanto/git/sstuv/documentos/views.py", line 180, in saveExpediente
    guardar_pase( depto_origen, depto_destino, expediente_instance )
  File "/home/mmanto/git/sstuv/documentos/views.py", line 440, in guardar_pase
    nuevo_pase.expediente = expediente
  File "/home/mmanto/virtualenvs3/python3.4/lib/python3.4/site-packages/django/db/models/fields/related.py", line 589, in __set__
    (instance._meta.object_name, self.field.name)
ValueError: Cannot assign None: "Pase.expediente" does not allow null values.
[08/May/2015 12:49:32] ERROR [django.request:231] Internal Server Error: /sig/expedientes/guardar/
Traceback (most recent call last):
  File "/home/mmanto/virtualenvs3/python3.4/lib/python3.4/site-packages/django/core/handlers/base.py", line 111, in get_response
    response = wrapped_callback(request, *callback_args, **callback_kwargs)
  File "/home/mmanto/virtualenvs3/python3.4/lib/python3.4/site-packages/django/contrib/auth/decorators.py", line 21, in _wrapped_view
    return view_func(request, *args, **kwargs)
  File "/home/mmanto/git/sstuv/documentos/views.py", line 177, in saveExpediente
    expediente_instance = exp.save_new(form)
AttributeError: 'Expediente' object has no attribute 'save_new'
[08/May/2015 12:50:57] ERROR [django.request:231] Internal Server Error: /sig/expedientes/guardar/
Traceback (most recent call last):
  File "/home/mmanto/virtualenvs3/python3.4/lib/python3.4/site-packages/django/core/handlers/base.py", line 111, in get_response
    response = wrapped_callback(request, *callback_args, **callback_kwargs)
  File "/home/mmanto/virtualenvs3/python3.4/lib/python3.4/site-packages/django/contrib/auth/decorators.py", line 21, in _wrapped_view
    return view_func(request, *args, **kwargs)
  File "/home/mmanto/git/sstuv/documentos/views.py", line 175, in saveExpediente
    exp.usuarioAlta=request.user.username
UnboundLocalError: local variable 'exp' referenced before assignment
[08/May/2015 12:51:19] ERROR [django.request:231] Internal Server Error: /sig/expedientes/guardar/
Traceback (most recent call last):
  File "/home/mmanto/virtualenvs3/python3.4/lib/python3.4/site-packages/django/core/handlers/base.py", line 111, in get_response
    response = wrapped_callback(request, *callback_args, **callback_kwargs)
  File "/home/mmanto/virtualenvs3/python3.4/lib/python3.4/site-packages/django/contrib/auth/decorators.py", line 21, in _wrapped_view
    return view_func(request, *args, **kwargs)
  File "/home/mmanto/git/sstuv/documentos/views.py", line 179, in saveExpediente
    guardar_pase( depto_origen, depto_destino, exp )
  File "/home/mmanto/git/sstuv/documentos/views.py", line 440, in guardar_pase
    nuevo_pase.save()
  File "/home/mmanto/virtualenvs3/python3.4/lib/python3.4/site-packages/django/db/models/base.py", line 589, in save
    force_update=force_update, update_fields=update_fields)
  File "/home/mmanto/virtualenvs3/python3.4/lib/python3.4/site-packages/django/db/models/base.py", line 617, in save_base
    updated = self._save_table(raw, cls, force_insert, force_update, using, update_fields)
  File "/home/mmanto/virtualenvs3/python3.4/lib/python3.4/site-packages/django/db/models/base.py", line 698, in _save_table
    result = self._do_insert(cls._base_manager, using, fields, update_pk, raw)
  File "/home/mmanto/virtualenvs3/python3.4/lib/python3.4/site-packages/django/db/models/base.py", line 731, in _do_insert
    using=using, raw=raw)
  File "/home/mmanto/virtualenvs3/python3.4/lib/python3.4/site-packages/django/db/models/manager.py", line 92, in manager_method
    return getattr(self.get_queryset(), name)(*args, **kwargs)
  File "/home/mmanto/virtualenvs3/python3.4/lib/python3.4/site-packages/django/db/models/query.py", line 921, in _insert
    return query.get_compiler(using=using).execute_sql(return_id)
  File "/home/mmanto/virtualenvs3/python3.4/lib/python3.4/site-packages/django/db/models/sql/compiler.py", line 919, in execute_sql
    for sql, params in self.as_sql():
  File "/home/mmanto/virtualenvs3/python3.4/lib/python3.4/site-packages/django/db/models/sql/compiler.py", line 877, in as_sql
    for obj in self.query.objs
  File "/home/mmanto/virtualenvs3/python3.4/lib/python3.4/site-packages/django/db/models/sql/compiler.py", line 877, in <listcomp>
    for obj in self.query.objs
  File "/home/mmanto/virtualenvs3/python3.4/lib/python3.4/site-packages/django/db/models/sql/compiler.py", line 875, in <listcomp>
    for f in fields
  File "/home/mmanto/virtualenvs3/python3.4/lib/python3.4/site-packages/django/db/models/fields/__init__.py", line 627, in get_db_prep_save
    prepared=False)
  File "/home/mmanto/virtualenvs3/python3.4/lib/python3.4/site-packages/django/db/models/fields/__init__.py", line 1290, in get_db_prep_value
    value = self.get_prep_value(value)
  File "/home/mmanto/virtualenvs3/python3.4/lib/python3.4/site-packages/django/db/models/fields/__init__.py", line 1269, in get_prep_value
    value = super(DateTimeField, self).get_prep_value(value)
  File "/home/mmanto/virtualenvs3/python3.4/lib/python3.4/site-packages/django/db/models/fields/__init__.py", line 1171, in get_prep_value
    return self.to_python(value)
  File "/home/mmanto/virtualenvs3/python3.4/lib/python3.4/site-packages/django/db/models/fields/__init__.py", line 1228, in to_python
    parsed = parse_datetime(value)
  File "/home/mmanto/virtualenvs3/python3.4/lib/python3.4/site-packages/django/utils/dateparse.py", line 70, in parse_datetime
    match = datetime_re.match(value)
TypeError: expected string or buffer
[08/May/2015 12:52:08] ERROR [django.request:231] Internal Server Error: /sig/expedientes/guardar/
Traceback (most recent call last):
  File "/home/mmanto/virtualenvs3/python3.4/lib/python3.4/site-packages/django/core/handlers/base.py", line 111, in get_response
    response = wrapped_callback(request, *callback_args, **callback_kwargs)
  File "/home/mmanto/virtualenvs3/python3.4/lib/python3.4/site-packages/django/contrib/auth/decorators.py", line 21, in _wrapped_view
    return view_func(request, *args, **kwargs)
  File "/home/mmanto/git/sstuv/documentos/views.py", line 180, in saveExpediente
    guardar_pase( depto_origen, depto_destino, exp )
  File "/home/mmanto/git/sstuv/documentos/views.py", line 441, in guardar_pase
    nuevo_pase.save()
  File "/home/mmanto/virtualenvs3/python3.4/lib/python3.4/site-packages/django/db/models/base.py", line 589, in save
    force_update=force_update, update_fields=update_fields)
  File "/home/mmanto/virtualenvs3/python3.4/lib/python3.4/site-packages/django/db/models/base.py", line 617, in save_base
    updated = self._save_table(raw, cls, force_insert, force_update, using, update_fields)
  File "/home/mmanto/virtualenvs3/python3.4/lib/python3.4/site-packages/django/db/models/base.py", line 698, in _save_table
    result = self._do_insert(cls._base_manager, using, fields, update_pk, raw)
  File "/home/mmanto/virtualenvs3/python3.4/lib/python3.4/site-packages/django/db/models/base.py", line 731, in _do_insert
    using=using, raw=raw)
  File "/home/mmanto/virtualenvs3/python3.4/lib/python3.4/site-packages/django/db/models/manager.py", line 92, in manager_method
    return getattr(self.get_queryset(), name)(*args, **kwargs)
  File "/home/mmanto/virtualenvs3/python3.4/lib/python3.4/site-packages/django/db/models/query.py", line 921, in _insert
    return query.get_compiler(using=using).execute_sql(return_id)
  File "/home/mmanto/virtualenvs3/python3.4/lib/python3.4/site-packages/django/db/models/sql/compiler.py", line 919, in execute_sql
    for sql, params in self.as_sql():
  File "/home/mmanto/virtualenvs3/python3.4/lib/python3.4/site-packages/django/db/models/sql/compiler.py", line 877, in as_sql
    for obj in self.query.objs
  File "/home/mmanto/virtualenvs3/python3.4/lib/python3.4/site-packages/django/db/models/sql/compiler.py", line 877, in <listcomp>
    for obj in self.query.objs
  File "/home/mmanto/virtualenvs3/python3.4/lib/python3.4/site-packages/django/db/models/sql/compiler.py", line 875, in <listcomp>
    for f in fields
  File "/home/mmanto/virtualenvs3/python3.4/lib/python3.4/site-packages/django/db/models/fields/__init__.py", line 627, in get_db_prep_save
    prepared=False)
  File "/home/mmanto/virtualenvs3/python3.4/lib/python3.4/site-packages/django/db/models/fields/__init__.py", line 1290, in get_db_prep_value
    value = self.get_prep_value(value)
  File "/home/mmanto/virtualenvs3/python3.4/lib/python3.4/site-packages/django/db/models/fields/__init__.py", line 1269, in get_prep_value
    value = super(DateTimeField, self).get_prep_value(value)
  File "/home/mmanto/virtualenvs3/python3.4/lib/python3.4/site-packages/django/db/models/fields/__init__.py", line 1171, in get_prep_value
    return self.to_python(value)
  File "/home/mmanto/virtualenvs3/python3.4/lib/python3.4/site-packages/django/db/models/fields/__init__.py", line 1228, in to_python
    parsed = parse_datetime(value)
  File "/home/mmanto/virtualenvs3/python3.4/lib/python3.4/site-packages/django/utils/dateparse.py", line 70, in parse_datetime
    match = datetime_re.match(value)
TypeError: expected string or buffer
[11/May/2015 17:44:48] ERROR [django.request:231] Internal Server Error: /sig
Traceback (most recent call last):
  File "/home/mmanto/virtualenvs3/python3.4/lib/python3.4/site-packages/django/core/urlresolvers.py", line 364, in urlconf_module
    return self._urlconf_module
AttributeError: 'RegexURLResolver' object has no attribute '_urlconf_module'

During handling of the above exception, another exception occurred:

Traceback (most recent call last):
  File "/home/mmanto/virtualenvs3/python3.4/lib/python3.4/site-packages/django/core/handlers/base.py", line 87, in get_response
    response = middleware_method(request)
  File "/home/mmanto/virtualenvs3/python3.4/lib/python3.4/site-packages/django/middleware/common.py", line 72, in process_request
    if (not urlresolvers.is_valid_path(request.path_info, urlconf) and
  File "/home/mmanto/virtualenvs3/python3.4/lib/python3.4/site-packages/django/core/urlresolvers.py", line 619, in is_valid_path
    resolve(path, urlconf)
  File "/home/mmanto/virtualenvs3/python3.4/lib/python3.4/site-packages/django/core/urlresolvers.py", line 494, in resolve
    return get_resolver(urlconf).resolve(path)
  File "/home/mmanto/virtualenvs3/python3.4/lib/python3.4/site-packages/django/core/urlresolvers.py", line 343, in resolve
    for pattern in self.url_patterns:
  File "/home/mmanto/virtualenvs3/python3.4/lib/python3.4/site-packages/django/core/urlresolvers.py", line 372, in url_patterns
    patterns = getattr(self.urlconf_module, "urlpatterns", self.urlconf_module)
  File "/home/mmanto/virtualenvs3/python3.4/lib/python3.4/site-packages/django/core/urlresolvers.py", line 366, in urlconf_module
    self._urlconf_module = import_module(self.urlconf_name)
  File "/home/mmanto/virtualenvs3/python3.4/lib/python3.4/importlib/__init__.py", line 109, in import_module
    return _bootstrap._gcd_import(name[level:], package, level)
  File "<frozen importlib._bootstrap>", line 2254, in _gcd_import
  File "<frozen importlib._bootstrap>", line 2237, in _find_and_load
  File "<frozen importlib._bootstrap>", line 2226, in _find_and_load_unlocked
  File "<frozen importlib._bootstrap>", line 1200, in _load_unlocked
  File "<frozen importlib._bootstrap>", line 1129, in _exec
  File "<frozen importlib._bootstrap>", line 1471, in exec_module
  File "<frozen importlib._bootstrap>", line 321, in _call_with_frames_removed
  File "/home/mmanto/git/sstuv/sstuv/urls.py", line 10, in <module>
    from procesos import procesos_sites
  File "/home/mmanto/git/sstuv/procesos/procesos_sites.py", line 3, in <module>
    from regularizacion import regularizacion_sites
  File "/home/mmanto/git/sstuv/regularizacion/regularizacion_sites.py", line 2, in <module>
    from regularizacion.views import CensoView
  File "/home/mmanto/git/sstuv/regularizacion/views.py", line 26, in <module>
    from comun.models import Partido, Departamento, Barrio
ImportError: cannot import name 'Barrio'
[11/May/2015 17:44:48] ERROR [django.request:231] Internal Server Error: /favicon.ico
Traceback (most recent call last):
  File "/home/mmanto/virtualenvs3/python3.4/lib/python3.4/site-packages/django/core/urlresolvers.py", line 364, in urlconf_module
    return self._urlconf_module
AttributeError: 'RegexURLResolver' object has no attribute '_urlconf_module'

During handling of the above exception, another exception occurred:

Traceback (most recent call last):
  File "/home/mmanto/virtualenvs3/python3.4/lib/python3.4/site-packages/django/core/handlers/base.py", line 87, in get_response
    response = middleware_method(request)
  File "/home/mmanto/virtualenvs3/python3.4/lib/python3.4/site-packages/django/middleware/common.py", line 72, in process_request
    if (not urlresolvers.is_valid_path(request.path_info, urlconf) and
  File "/home/mmanto/virtualenvs3/python3.4/lib/python3.4/site-packages/django/core/urlresolvers.py", line 619, in is_valid_path
    resolve(path, urlconf)
  File "/home/mmanto/virtualenvs3/python3.4/lib/python3.4/site-packages/django/core/urlresolvers.py", line 494, in resolve
    return get_resolver(urlconf).resolve(path)
  File "/home/mmanto/virtualenvs3/python3.4/lib/python3.4/site-packages/django/core/urlresolvers.py", line 343, in resolve
    for pattern in self.url_patterns:
  File "/home/mmanto/virtualenvs3/python3.4/lib/python3.4/site-packages/django/core/urlresolvers.py", line 372, in url_patterns
    patterns = getattr(self.urlconf_module, "urlpatterns", self.urlconf_module)
  File "/home/mmanto/virtualenvs3/python3.4/lib/python3.4/site-packages/django/core/urlresolvers.py", line 366, in urlconf_module
    self._urlconf_module = import_module(self.urlconf_name)
  File "/home/mmanto/virtualenvs3/python3.4/lib/python3.4/importlib/__init__.py", line 109, in import_module
    return _bootstrap._gcd_import(name[level:], package, level)
  File "<frozen importlib._bootstrap>", line 2254, in _gcd_import
  File "<frozen importlib._bootstrap>", line 2237, in _find_and_load
  File "<frozen importlib._bootstrap>", line 2226, in _find_and_load_unlocked
  File "<frozen importlib._bootstrap>", line 1200, in _load_unlocked
  File "<frozen importlib._bootstrap>", line 1129, in _exec
  File "<frozen importlib._bootstrap>", line 1471, in exec_module
  File "<frozen importlib._bootstrap>", line 321, in _call_with_frames_removed
  File "/home/mmanto/git/sstuv/sstuv/urls.py", line 10, in <module>
    from procesos import procesos_sites
  File "/home/mmanto/git/sstuv/procesos/procesos_sites.py", line 3, in <module>
    from regularizacion import regularizacion_sites
  File "/home/mmanto/git/sstuv/regularizacion/regularizacion_sites.py", line 2, in <module>
    from regularizacion.views import CensoView
  File "/home/mmanto/git/sstuv/regularizacion/views.py", line 26, in <module>
    from comun.models import Partido, Departamento, Barrio
ImportError: cannot import name 'Barrio'
[11/May/2015 17:45:25] INFO [sstuvInfo:94] busqueda de expedientes en logger info
[11/May/2015 17:45:25] WARNING [django.request:143] Not Found: /favicon.ico
[13/May/2015 13:46:57] INFO [sstuvInfo:94] busqueda de expedientes en logger info
[13/May/2015 13:46:58] WARNING [django.request:143] Not Found: /favicon.ico
[15/May/2015 18:43:57] INFO [sstuvInfo:94] busqueda de expedientes en logger info
[15/May/2015 18:43:58] WARNING [django.request:143] Not Found: /favicon.ico
[15/May/2015 19:11:09] ERROR [django.request:231] Internal Server Error: /sig/expedientes/guardar/
Traceback (most recent call last):
  File "/home/mmanto/virtualenvs3/python3.4/lib/python3.4/site-packages/django/db/backends/utils.py", line 65, in execute
    return self.cursor.execute(sql, params)
psycopg2.ProgrammingError: no existe la columna documentos_expediente.anio
LINE 1: ..."documentos_expediente"."numero" = '22121121' AND "documento...
                                                             ^


The above exception was the direct cause of the following exception:

Traceback (most recent call last):
  File "/home/mmanto/virtualenvs3/python3.4/lib/python3.4/site-packages/django/core/handlers/base.py", line 111, in get_response
    response = wrapped_callback(request, *callback_args, **callback_kwargs)
  File "/home/mmanto/virtualenvs3/python3.4/lib/python3.4/site-packages/django/contrib/auth/decorators.py", line 21, in _wrapped_view
    return view_func(request, *args, **kwargs)
  File "/home/mmanto/git/sstuv/documentos/views.py", line 171, in saveExpediente
    if(Expediente.objects.filter(organismo=request.POST.get('organismo') , numero=request.POST.get('numero'), anio=request.POST.get('anio')).exists()):
  File "/home/mmanto/virtualenvs3/python3.4/lib/python3.4/site-packages/django/db/models/query.py", line 606, in exists
    return self.query.has_results(using=self.db)
  File "/home/mmanto/virtualenvs3/python3.4/lib/python3.4/site-packages/django/db/models/sql/query.py", line 457, in has_results
    return compiler.has_results()
  File "/home/mmanto/virtualenvs3/python3.4/lib/python3.4/site-packages/django/db/models/sql/compiler.py", line 757, in has_results
    return bool(self.execute_sql(SINGLE))
  File "/home/mmanto/virtualenvs3/python3.4/lib/python3.4/site-packages/django/db/models/sql/compiler.py", line 786, in execute_sql
    cursor.execute(sql, params)
  File "/home/mmanto/virtualenvs3/python3.4/lib/python3.4/site-packages/django/db/backends/utils.py", line 81, in execute
    return super(CursorDebugWrapper, self).execute(sql, params)
  File "/home/mmanto/virtualenvs3/python3.4/lib/python3.4/site-packages/django/db/backends/utils.py", line 65, in execute
    return self.cursor.execute(sql, params)
  File "/home/mmanto/virtualenvs3/python3.4/lib/python3.4/site-packages/django/db/utils.py", line 94, in __exit__
    six.reraise(dj_exc_type, dj_exc_value, traceback)
  File "/home/mmanto/virtualenvs3/python3.4/lib/python3.4/site-packages/django/utils/six.py", line 658, in reraise
    raise value.with_traceback(tb)
  File "/home/mmanto/virtualenvs3/python3.4/lib/python3.4/site-packages/django/db/backends/utils.py", line 65, in execute
    return self.cursor.execute(sql, params)
django.db.utils.ProgrammingError: no existe la columna documentos_expediente.anio
LINE 1: ..."documentos_expediente"."numero" = '22121121' AND "documento...
                                                             ^

[15/May/2015 19:17:11] ERROR [django.request:231] Internal Server Error: /sig/expedientes/guardar/
Traceback (most recent call last):
  File "/home/mmanto/virtualenvs3/python3.4/lib/python3.4/site-packages/django/db/backends/utils.py", line 65, in execute
    return self.cursor.execute(sql, params)
psycopg2.ProgrammingError: el operador no existe: date = integer
LINE 1: ..." = '22121121' AND "documentos_expediente"."anio" = 2025) LI...
                                                             ^
HINT:  Ningún operador coincide con el nombre y el tipo de los argumentos. Puede ser necesario agregar conversiones explícitas de tipos.


The above exception was the direct cause of the following exception:

Traceback (most recent call last):
  File "/home/mmanto/virtualenvs3/python3.4/lib/python3.4/site-packages/django/core/handlers/base.py", line 111, in get_response
    response = wrapped_callback(request, *callback_args, **callback_kwargs)
  File "/home/mmanto/virtualenvs3/python3.4/lib/python3.4/site-packages/django/contrib/auth/decorators.py", line 21, in _wrapped_view
    return view_func(request, *args, **kwargs)
  File "/home/mmanto/git/sstuv/documentos/views.py", line 171, in saveExpediente
    if(Expediente.objects.filter(organismo=request.POST.get('organismo') , numero=request.POST.get('numero'), anio=request.POST.get('anio')).exists()):
  File "/home/mmanto/virtualenvs3/python3.4/lib/python3.4/site-packages/django/db/models/query.py", line 606, in exists
    return self.query.has_results(using=self.db)
  File "/home/mmanto/virtualenvs3/python3.4/lib/python3.4/site-packages/django/db/models/sql/query.py", line 457, in has_results
    return compiler.has_results()
  File "/home/mmanto/virtualenvs3/python3.4/lib/python3.4/site-packages/django/db/models/sql/compiler.py", line 757, in has_results
    return bool(self.execute_sql(SINGLE))
  File "/home/mmanto/virtualenvs3/python3.4/lib/python3.4/site-packages/django/db/models/sql/compiler.py", line 786, in execute_sql
    cursor.execute(sql, params)
  File "/home/mmanto/virtualenvs3/python3.4/lib/python3.4/site-packages/django/db/backends/utils.py", line 81, in execute
    return super(CursorDebugWrapper, self).execute(sql, params)
  File "/home/mmanto/virtualenvs3/python3.4/lib/python3.4/site-packages/django/db/backends/utils.py", line 65, in execute
    return self.cursor.execute(sql, params)
  File "/home/mmanto/virtualenvs3/python3.4/lib/python3.4/site-packages/django/db/utils.py", line 94, in __exit__
    six.reraise(dj_exc_type, dj_exc_value, traceback)
  File "/home/mmanto/virtualenvs3/python3.4/lib/python3.4/site-packages/django/utils/six.py", line 658, in reraise
    raise value.with_traceback(tb)
  File "/home/mmanto/virtualenvs3/python3.4/lib/python3.4/site-packages/django/db/backends/utils.py", line 65, in execute
    return self.cursor.execute(sql, params)
django.db.utils.ProgrammingError: el operador no existe: date = integer
LINE 1: ..." = '22121121' AND "documentos_expediente"."anio" = 2025) LI...
                                                             ^
HINT:  Ningún operador coincide con el nombre y el tipo de los argumentos. Puede ser necesario agregar conversiones explícitas de tipos.

[15/May/2015 19:23:50] ERROR [django.request:231] Internal Server Error: /sig/expedientes/guardar/
Traceback (most recent call last):
  File "/home/mmanto/virtualenvs3/python3.4/lib/python3.4/site-packages/django/db/backends/utils.py", line 65, in execute
    return self.cursor.execute(sql, params)
psycopg2.ProgrammingError: el operador no existe: date = integer
LINE 1: ...o" = '4141414' AND "documentos_expediente"."anio" = 2015) LI...
                                                             ^
HINT:  Ningún operador coincide con el nombre y el tipo de los argumentos. Puede ser necesario agregar conversiones explícitas de tipos.


The above exception was the direct cause of the following exception:

Traceback (most recent call last):
  File "/home/mmanto/virtualenvs3/python3.4/lib/python3.4/site-packages/django/core/handlers/base.py", line 111, in get_response
    response = wrapped_callback(request, *callback_args, **callback_kwargs)
  File "/home/mmanto/virtualenvs3/python3.4/lib/python3.4/site-packages/django/contrib/auth/decorators.py", line 21, in _wrapped_view
    return view_func(request, *args, **kwargs)
  File "/home/mmanto/git/sstuv/documentos/views.py", line 171, in saveExpediente
    if(Expediente.objects.filter(organismo=request.POST.get('organismo') , numero=request.POST.get('numero'), anio=request.POST.get('anio')).exists()):
  File "/home/mmanto/virtualenvs3/python3.4/lib/python3.4/site-packages/django/db/models/query.py", line 606, in exists
    return self.query.has_results(using=self.db)
  File "/home/mmanto/virtualenvs3/python3.4/lib/python3.4/site-packages/django/db/models/sql/query.py", line 457, in has_results
    return compiler.has_results()
  File "/home/mmanto/virtualenvs3/python3.4/lib/python3.4/site-packages/django/db/models/sql/compiler.py", line 757, in has_results
    return bool(self.execute_sql(SINGLE))
  File "/home/mmanto/virtualenvs3/python3.4/lib/python3.4/site-packages/django/db/models/sql/compiler.py", line 786, in execute_sql
    cursor.execute(sql, params)
  File "/home/mmanto/virtualenvs3/python3.4/lib/python3.4/site-packages/django/db/backends/utils.py", line 81, in execute
    return super(CursorDebugWrapper, self).execute(sql, params)
  File "/home/mmanto/virtualenvs3/python3.4/lib/python3.4/site-packages/django/db/backends/utils.py", line 65, in execute
    return self.cursor.execute(sql, params)
  File "/home/mmanto/virtualenvs3/python3.4/lib/python3.4/site-packages/django/db/utils.py", line 94, in __exit__
    six.reraise(dj_exc_type, dj_exc_value, traceback)
  File "/home/mmanto/virtualenvs3/python3.4/lib/python3.4/site-packages/django/utils/six.py", line 658, in reraise
    raise value.with_traceback(tb)
  File "/home/mmanto/virtualenvs3/python3.4/lib/python3.4/site-packages/django/db/backends/utils.py", line 65, in execute
    return self.cursor.execute(sql, params)
django.db.utils.ProgrammingError: el operador no existe: date = integer
LINE 1: ...o" = '4141414' AND "documentos_expediente"."anio" = 2015) LI...
                                                             ^
HINT:  Ningún operador coincide con el nombre y el tipo de los argumentos. Puede ser necesario agregar conversiones explícitas de tipos.

[19/May/2015 17:47:44] INFO [sstuvInfo:94] busqueda de expedientes en logger info
[19/May/2015 17:47:45] WARNING [django.request:143] Not Found: /favicon.ico
[19/May/2015 17:49:48] ERROR [django.request:231] Internal Server Error: /sig/expedientes/guardar/
Traceback (most recent call last):
  File "/home/mmanto/virtualenvs3/python3.4/lib/python3.4/site-packages/django/db/backends/utils.py", line 65, in execute
    return self.cursor.execute(sql, params)
psycopg2.ProgrammingError: el operador no existe: date = integer
LINE 1: ...= '6888888882' AND "documentos_expediente"."anio" = 2025) LI...
                                                             ^
HINT:  Ningún operador coincide con el nombre y el tipo de los argumentos. Puede ser necesario agregar conversiones explícitas de tipos.


The above exception was the direct cause of the following exception:

Traceback (most recent call last):
  File "/home/mmanto/virtualenvs3/python3.4/lib/python3.4/site-packages/django/core/handlers/base.py", line 111, in get_response
    response = wrapped_callback(request, *callback_args, **callback_kwargs)
  File "/home/mmanto/virtualenvs3/python3.4/lib/python3.4/site-packages/django/contrib/auth/decorators.py", line 21, in _wrapped_view
    return view_func(request, *args, **kwargs)
  File "/home/mmanto/git/sstuv/documentos/views.py", line 171, in saveExpediente
    if(Expediente.objects.filter(organismo=request.POST.get('organismo') , numero=request.POST.get('numero'), anio=request.POST.get('anio')).exists()):
  File "/home/mmanto/virtualenvs3/python3.4/lib/python3.4/site-packages/django/db/models/query.py", line 606, in exists
    return self.query.has_results(using=self.db)
  File "/home/mmanto/virtualenvs3/python3.4/lib/python3.4/site-packages/django/db/models/sql/query.py", line 457, in has_results
    return compiler.has_results()
  File "/home/mmanto/virtualenvs3/python3.4/lib/python3.4/site-packages/django/db/models/sql/compiler.py", line 757, in has_results
    return bool(self.execute_sql(SINGLE))
  File "/home/mmanto/virtualenvs3/python3.4/lib/python3.4/site-packages/django/db/models/sql/compiler.py", line 786, in execute_sql
    cursor.execute(sql, params)
  File "/home/mmanto/virtualenvs3/python3.4/lib/python3.4/site-packages/django/db/backends/utils.py", line 81, in execute
    return super(CursorDebugWrapper, self).execute(sql, params)
  File "/home/mmanto/virtualenvs3/python3.4/lib/python3.4/site-packages/django/db/backends/utils.py", line 65, in execute
    return self.cursor.execute(sql, params)
  File "/home/mmanto/virtualenvs3/python3.4/lib/python3.4/site-packages/django/db/utils.py", line 94, in __exit__
    six.reraise(dj_exc_type, dj_exc_value, traceback)
  File "/home/mmanto/virtualenvs3/python3.4/lib/python3.4/site-packages/django/utils/six.py", line 658, in reraise
    raise value.with_traceback(tb)
  File "/home/mmanto/virtualenvs3/python3.4/lib/python3.4/site-packages/django/db/backends/utils.py", line 65, in execute
    return self.cursor.execute(sql, params)
django.db.utils.ProgrammingError: el operador no existe: date = integer
LINE 1: ...= '6888888882' AND "documentos_expediente"."anio" = 2025) LI...
                                                             ^
HINT:  Ningún operador coincide con el nombre y el tipo de los argumentos. Puede ser necesario agregar conversiones explícitas de tipos.

[20/May/2015 13:46:44] INFO [sstuvInfo:94] busqueda de expedientes en logger info
[20/May/2015 13:47:13] ERROR [django.request:231] Internal Server Error: /sig/expedientes/guardar/
Traceback (most recent call last):
  File "/home/mmanto/virtualenvs3/python3.4/lib/python3.4/site-packages/django/db/backends/utils.py", line 65, in execute
    return self.cursor.execute(sql, params)
psycopg2.IntegrityError: el valor null para la columna «fecha_inicio» viola la restricción not null
DETAIL:  La fila que falla contiene (154080, ca1, 65656565, null, 0, 0, null, f, 2423,  
sfasdfga				
		                                             ..., 1,  
		 		
asdasdf
		                                           ..., 2025-05-01,                                                                 ..., 2025).


The above exception was the direct cause of the following exception:

Traceback (most recent call last):
  File "/home/mmanto/virtualenvs3/python3.4/lib/python3.4/site-packages/django/core/handlers/base.py", line 111, in get_response
    response = wrapped_callback(request, *callback_args, **callback_kwargs)
  File "/home/mmanto/virtualenvs3/python3.4/lib/python3.4/site-packages/django/contrib/auth/decorators.py", line 21, in _wrapped_view
    return view_func(request, *args, **kwargs)
  File "/home/mmanto/git/sstuv/documentos/views.py", line 175, in saveExpediente
    exp =  form.save()
  File "/home/mmanto/virtualenvs3/python3.4/lib/python3.4/site-packages/django/forms/models.py", line 455, in save
    construct=False)
  File "/home/mmanto/virtualenvs3/python3.4/lib/python3.4/site-packages/django/forms/models.py", line 103, in save_instance
    instance.save()
  File "/home/mmanto/virtualenvs3/python3.4/lib/python3.4/site-packages/django/db/models/base.py", line 589, in save
    force_update=force_update, update_fields=update_fields)
  File "/home/mmanto/virtualenvs3/python3.4/lib/python3.4/site-packages/django/db/models/base.py", line 617, in save_base
    updated = self._save_table(raw, cls, force_insert, force_update, using, update_fields)
  File "/home/mmanto/virtualenvs3/python3.4/lib/python3.4/site-packages/django/db/models/base.py", line 698, in _save_table
    result = self._do_insert(cls._base_manager, using, fields, update_pk, raw)
  File "/home/mmanto/virtualenvs3/python3.4/lib/python3.4/site-packages/django/db/models/base.py", line 731, in _do_insert
    using=using, raw=raw)
  File "/home/mmanto/virtualenvs3/python3.4/lib/python3.4/site-packages/django/db/models/manager.py", line 92, in manager_method
    return getattr(self.get_queryset(), name)(*args, **kwargs)
  File "/home/mmanto/virtualenvs3/python3.4/lib/python3.4/site-packages/django/db/models/query.py", line 921, in _insert
    return query.get_compiler(using=using).execute_sql(return_id)
  File "/home/mmanto/virtualenvs3/python3.4/lib/python3.4/site-packages/django/db/models/sql/compiler.py", line 920, in execute_sql
    cursor.execute(sql, params)
  File "/home/mmanto/virtualenvs3/python3.4/lib/python3.4/site-packages/django/db/backends/utils.py", line 81, in execute
    return super(CursorDebugWrapper, self).execute(sql, params)
  File "/home/mmanto/virtualenvs3/python3.4/lib/python3.4/site-packages/django/db/backends/utils.py", line 65, in execute
    return self.cursor.execute(sql, params)
  File "/home/mmanto/virtualenvs3/python3.4/lib/python3.4/site-packages/django/db/utils.py", line 94, in __exit__
    six.reraise(dj_exc_type, dj_exc_value, traceback)
  File "/home/mmanto/virtualenvs3/python3.4/lib/python3.4/site-packages/django/utils/six.py", line 658, in reraise
    raise value.with_traceback(tb)
  File "/home/mmanto/virtualenvs3/python3.4/lib/python3.4/site-packages/django/db/backends/utils.py", line 65, in execute
    return self.cursor.execute(sql, params)
django.db.utils.IntegrityError: el valor null para la columna «fecha_inicio» viola la restricción not null
DETAIL:  La fila que falla contiene (154080, ca1, 65656565, null, 0, 0, null, f, 2423,  
sfasdfga				
		                                             ..., 1,  
		 		
asdasdf
		                                           ..., 2025-05-01,                                                                 ..., 2025).

[20/May/2015 13:49:47] INFO [sstuvInfo:94] busqueda de expedientes en logger info
[20/May/2015 13:51:16] ERROR [django.request:231] Internal Server Error: /sig/pase/guardar/
Traceback (most recent call last):
  File "/home/mmanto/virtualenvs3/python3.4/lib/python3.4/site-packages/django/core/handlers/base.py", line 111, in get_response
    response = wrapped_callback(request, *callback_args, **callback_kwargs)
  File "/home/mmanto/virtualenvs3/python3.4/lib/python3.4/site-packages/django/contrib/auth/decorators.py", line 21, in _wrapped_view
    return view_func(request, *args, **kwargs)
  File "/home/mmanto/git/sstuv/documentos/views.py", line 378, in savePase
    pase.fecha = datetime.datetime.strptime(fecha, "%d/%m/%Y")
TypeError: must be str, not None
[20/May/2015 13:53:13] ERROR [django.request:231] Internal Server Error: /sig/pase/guardar/
Traceback (most recent call last):
  File "/home/mmanto/virtualenvs3/python3.4/lib/python3.4/site-packages/django/core/handlers/base.py", line 111, in get_response
    response = wrapped_callback(request, *callback_args, **callback_kwargs)
  File "/home/mmanto/virtualenvs3/python3.4/lib/python3.4/site-packages/django/contrib/auth/decorators.py", line 21, in _wrapped_view
    return view_func(request, *args, **kwargs)
  File "/home/mmanto/git/sstuv/documentos/views.py", line 378, in savePase
    pase.fecha = datetime.datetime.strptime(fecha, "%d/%m/%Y")
TypeError: must be str, not None
[20/May/2015 13:53:43] INFO [sstuvInfo:94] busqueda de expedientes en logger info
[20/May/2015 13:55:18] INFO [sstuvInfo:94] busqueda de expedientes en logger info
[20/May/2015 13:55:27] INFO [sstuvInfo:94] busqueda de expedientes en logger info
[22/May/2015 14:36:24] WARNING [django.request:143] Not Found: /favicon.ico
[22/May/2015 14:36:41] INFO [sstuvInfo:94] busqueda de expedientes en logger info
[22/May/2015 14:36:41] WARNING [django.request:143] Not Found: /favicon.ico
